Workbook

Sheet 使い方
A1: ローンチチーム管理表｜使い方と運用ルール
A2: 黄色セル＝入力欄／白セル＝自動計算（触らない） ※メニュー「🚀ローンチ管理」はGAS（Code.gs）を入れると表示されます
A4: ■ 全体の流れ
B5: 声かけ → 【CCS追っかけ】で入会まで追う → 申込書・入金・同意書の3つに✓ → 自動で【入会後行動リスト】に本人とDNAのタスクが作られる → 毎日決まった時刻に、遅れている人・LINE未参加の人をメールでアラート
A6: ■ シート構成
A7: 📊ダッシュボード | B7: 全ローンチの進捗・信号・体制・入会後タスクの遅れを一覧（自動計算）。週次ローンチMTGはこの画面で進行。
A8: 全体管理 | B8: 従来の全体管理表と同じ並び。各LDシートから自動集約（入力不要）。
A9: 週次推移 | B9: 10/5スタートの13週（年末まで）。声かけ・面談・CCS実施・正式化の週ごとの推移。開始日は設定シートで変更可。
A10: CCS追っかけ | B10: リストアップ〜入会までの台帳。1人1行。担当（リストアップしたメンバー）がCCSまで追いかける。現状・次のアクション・期日を入れ、申込書・振込控え・プリコア同意書の3点✓で『✅正式』。
A11: 担当別CCS | B11: ローンチ×担当メンバーごとの、リストアップ数・お誘い中・CCS済・入会数（GASが毎日更新）。
A12: 入会後行動リスト | B12: 入会者ごとの行動（本人のタスク＋DNAのタスク）。GASが自動で作成。完了したら✓。LINEグループに入ったのを確認したら『LINEグループに参加』に✓。
A13: 入会後進捗 | B13: 入会者×行動のマトリクス（GASが毎日自動更新）。誰が何で止まっているかを一目で確認。
A14: 日次ログ | B14: 毎日の活動を1ローンチ1行で記録。
A15: 各LDシート | B15: LDが自分のチーム形成・フェーズ情報を入力。
A16: 行動マスタ | B16: 入会後の流れ（ハルモニアのメンバー表の項目）。本人/DNA・担当ロール・期限=正式化日+何日・本人リマインド要否。ここを変えると次の入会者から反映。
A17: 通知先 | B17: ローンチごとのLDメール・CC・メンバー用LINEグループ招待URLと、DNAのメールアドレス。
A18: 設定 | B18: 期限日数・アラートの判定日数・プルダウン項目。
A19: アラートログ | B19: メール送信履歴（自動）。
A20: ■ 毎日（担当メンバー・LD・5分）
B21: ① 担当メンバー：届いたメールを見て見込み客に連絡 → CCS追っかけの現状・次のアクション・期日を更新（編集すると最終接触日が自動で今日になります）
B22: ② 入会後行動リストで終わったタスクに✓（完了日は自動） ③ 日次ログに1行（0の日も0で入力）
A23: ■ 毎週（月曜 9:00 ローンチMTG前まで）
B24: 各LDシートの『ローンチ進捗』を更新 → MTGはダッシュボードの🔴→🟡→🟢の順に確認
A25: ■ 自動アラート（メール）
B26: 毎日決まった時刻にメールが届きます：①ローンチまとめ（LD＋CC宛て）②自分の担当分だけ（担当メンバー・DNA宛て）③全ローンチのまとめ（OM宛て）
B27: アラート対象：期日超過／最終接触からN日放置／CCS後の申込待ち・振込待ち・同意書待ち／次アクション未設定／入会後タスクの期限切れ（LINEグループ未参加は初回定例会が近いと⚠付きで先頭に）
B28: 本人へのリマインドメール（LINE招待URL付き）は、行動マスタで『要』のタスクだけ。GASのCONFIGでONにします。
B29: メールの『シートを開く』ボタンから、そのまま管理表に飛べます。アラートが0件の人にはメールは届きません。
A30: ■ メールを見落とさないために（DNAにお願いすること）
B31: ① スマホのGmailアプリで、送信元アドレスを連絡先に登録し、通知をONにする
B32: ② 件名が【要対応】【ローンチアラート】で始まるメールにスターを付けるフィルタを作る（Gmail → 設定 → フィルタ）
A33: ■ ルール（RCS ローンチ方針より）
B34: ・プリコア人数は『申込書提出・入金・プリコア同意書』の3つが揃った人のみカウント
B35: ・フェーズ1は6週間、フェーズ2は4週間が期限。期限内未達の場合は全員と面談し、①継続 ②他チャプター紹介 ③返金 の3択を提示
B36: ・フェーズ3以降はメンバー都合の返金不可。フェーズ3 Week1で必ず説明しコミットメントを取り付ける
B37: ・新メンバーには必ずウェルカムコール／1年目メンバーにはベーシック受講を確認（行動マスタに組み込み済み）
A38: ■ GASの入れ方
B39: ① Googleスプレッドシートで開く → 拡張機能 → Apps Script → Code.gs に貼り付けて保存
B40: ② シートを再読み込み → メニュー「🚀ローンチ管理」→「初期チェック」→ 権限を許可
B41: ③ 通知先シートにLDメールと、担当メンバー・DNAのメールを入力 →「アラートをプレビュー」で内容確認 →「今すぐ送信」（最初はTEST_MODEでOMにだけ届く）
...

Sheet 📊ダッシュボード
A1: 📊 ローンチ ダッシュボード（全チーム）
A2: A列にLD名（シート名と同じ）を入れるだけで自動集計。🔴→🟡→🟢の順に週次MTGで確認
A4: 稼働中ローンチ | B4: 正式プリコア合計 | C4: 🔴 要対策 | D4: 🟡 要注意 | E4: 直近7日 面談合計 | F4: 本日ログ入力数 | G4: ログ停滞ローンチ | H4: 入会前アラート | I4: 入会後タスク遅れ | J4: LINEグループ未招待
A5: =COUNTIF(E8:E27,"フェーズ*") | B5: =SUM(J8:J27) | C5: =COUNTIF(M8:M27,"🔴*") | D5: =COUNTIF(M8:M27,"🟡*") | E5: =SUM(O8:O27) | F5: =COUNTIF('日次ログ'!$A$5:$A$1504,TODAY()) | G5: =SUMPRODUCT((LEFT(E8:E27,4)="フェーズ")*(((P8:P27="")+(IFERROR(TODAY()-P8:P27,0)>='設定'!$B$8))>0)) | H5: =COUNTIF('CCS追っかけ'!$W$5:$W$504,"?*") | I5: =COUNTIF('入会後行動リスト'!$J$5:$J$2004,"期限超過") | J5: =COUNTIFS('入会後行動リスト'!$D$5:$D$2004,"*LINEグループ*",'入会後行動リスト'!$H$5:$H$2004,"<>✓")
A7: ローンチディレクター | B7: チーム | C7: チャプター名 | D7: 初回定例会目安 | E7: 現フェーズ | F7: フェーズ開始日 | G7: フェーズ期限 | H7: 残日数 | I7: 目標人数 | J7: 正式プリコア | K7: 手続き中・入会前 | L7: 達成率 | M7: 判定 | N7: 直近7日 声かけ | O7: 直近7日 面談 | P7: 最終ログ日 | Q7: 体制 (承諾/記入) | R7: 今週の課題・EDへの相談 | S7: 詳細シート | T7: 入会後 タスク遅れ | U7: CCS済 （累計）
A8: 竹尾純子 | B8: =IF($A8="","",IFERROR(IF(INDIRECT("'"&$A8&"'!B4")="","",INDIRECT("'"&$A8&"'!B4")),"")) | C8: =IF($A8="","",IFERROR(IF(INDIRECT("'"&$A8&"'!B6")="","",INDIRECT("'"&$A8&"'!B6")),"")) | D8: =IF($A8="","",IFERROR(IF(INDIRECT("'"&$A8&"'!B8")="","",INDIRECT("'"&$A8&"'!B8")),"")) | E8: =IF($A8="","",IFERROR(IF(INDIRECT("'"&$A8&"'!B24")="","",INDIRECT("'"&$A8&"'!B24")),"")) | F8: =IF($A8="","",IFERROR(IF(INDIRECT("'"&$A8&"'!B25")="","",INDIRECT("'"&$A8&"'!B25")),"")) | G8: =IF(OR($A8="",F8=""),"",IF(E8="フェーズ1",F8+'設定'!$B$4,IF(E8="フェーズ2",F8+'設定'!$B$5,""))) | H8: =IF(G8="","",G8-TODAY()) | I8: =IF($A8="","",IFERROR(IF(INDIRECT("'"&$A8&"'!B26")="","",INDIRECT("'"&$A8&"'!B26")),"")) | J8: =IF($A8="","",COUNTIFS('CCS追っかけ'!$B$5:$B$504,$A8,'CCS追っかけ'!$P$5:$P$504,"✅正式")) | K8: =IF($A8="","",COUNTIFS('CCS追っかけ'!$B$5:$B$504,$A8,'CCS追っかけ'!$D$5:$D$504,"<>",'CCS追っかけ'!$V$5:$V$504,"<>辞退")-J8) | L8: =IF(OR($A8="",I8="",I8=0),"",J8/I8) | M8: =IF(OR($A8="",I8="",F8=""),"",IF(J8>=I8,"🟢達成",IF(G8="","🟡進行中",IF(H8<0,"🔴期限超過",IF(AND(H8<='設定'!$B$7,J8<I8*0.8),"🔴期限間近",IF(J8>=I8*MIN(1,(TODAY()-F8)/(G8-F8)),"🟢順調",IF(J8>=I8*MIN(1,(TODAY()-F8)/(G8-F8))*'設定'!$B$6,"🟡要注意","🔴遅れ"))))))) | N8: =IF($A8="","",SUMIFS('日次ログ'!$D$5:$D$1504,'日次ログ'!$B$5:$B$1504,$A8,'日次ログ'!$A$5:$A$1504,">="&(TODAY()-6))) | O8: =IF($A8="","",SUMIFS('日次ログ'!$F$5:$F$1504,'日次ログ'!$B$5:$B$1504,$A8,'日次ログ'!$A$5:$A$1504,">="&(TODAY()-6))) | P8: =IF($A8="","",IF(COUNTIF('日次ログ'!$B$5:$B$1504,$A8)=0,"",_xlfn.MAXIFS('日次ログ'!$A$5:$A$1504,'日次ログ'!$B$5:$B$1504,$A8))) | Q8: =IF($A8="","",IFERROR(COUNTIF(INDIRECT("'"&$A8&"'!E9:E21"),"承諾")&" / "&COUNTA(INDIRECT("'"&$A8&"'!B9:B21")),"")) | R8: =IF($A8="","",IFERROR(IF(INDIRECT("'"&$A8&"'!B27")="","",INDIRECT("'"&$A8&"'!B27")),"")) | S8: =IF($A8="","",IFERROR(IF(INDIRECT("'"&$A8&"'!B28")="","",INDIRECT("'"&$A8&"'!B28")),"")) | T8: =IF($A8="","",COUNTIFS('入会後行動リスト'!$B$5:$B$2004,$A8,'入会後行動リスト'!$J$5:$J$2004,"期限超過")) | U8: =IF($A8="","",COUNTIFS('CCS追っかけ'!$B$5:$B$504,$A8,'CCS追っかけ'!$J$5:$J$504,"CCS済")+COUNTIFS('CCS追っかけ'!$B$5:$B$504,$A8,'CCS追っかけ'!$P$5:$P$504,"✅正式",'CCS追っかけ'!$J$5:$J$504,"<>CCS済"))
A9: 福重孝一 | B9: =IF($A9="","",IFERROR(IF(INDIRECT("'"&$A9&"'!B4")="","",INDIRECT("'"&$A9&"'!B4")),"")) | C9: =IF($A9="","",IFERROR(IF(INDIRECT("'"&$A9&"'!B6")="","",INDIRECT("'"&$A9&"'!B6")),"")) | D9: =IF($A9="","",IFERROR(IF(INDIRECT("'"&$A9&"'!B8")="","",INDIRECT("'"&$A9&"'!B8")),"")) | E9: =IF($A9="","",IFERROR(IF(INDIRECT("'"&$A9&"'!B24")="","",INDIRECT("'"&$A9&"'!B24")),"")) | F9: =IF($A9="","",IFERROR(IF(INDIRECT("'"&$A9&"'!B25")="","",INDIRECT("'"&$A9&"'!B25")),"")) | G9: =IF(OR($A9="",F9=""),"",IF(E9="フェーズ1",F9+'設定'!$B$4,IF(E9="フェーズ2",F9+'設定'!$B$5,""))) | H9: =IF(G9="","",G9-TODAY()) | I9: =IF($A9="","",IFERROR(IF(INDIRECT("'"&$A9&"'!B26")="","",INDIRECT("'"&$A9&"'!B26")),"")) | J9: =IF($A9="","",COUNTIFS('CCS追っかけ'!$B$5:$B$504,$A9,'CCS追っかけ'!$P$5:$P$504,"✅正式")) | K9: =IF($A9="","",COUNTIFS('CCS追っかけ'!$B$5:$B$504,$A9,'CCS追っかけ'!$D$5:$D$504,"<>",'CCS追っかけ'!$V$5:$V$504,"<>辞退")-J9) | L9: =IF(OR($A9="",I9="",I9=0),"",J9/I9) | M9: =IF(OR($A9="",I9="",F9=""),"",IF(J9>=I9,"🟢達成",IF(G9="","🟡進行中",IF(H9<0,"🔴期限超過",IF(AND(H9<='設定'!$B$7,J9<I9*0.8),"🔴期限間近",IF(J9>=I9*MIN(1,(TODAY()-F9)/(G9-F9)),"🟢順調",IF(J9>=I9*MIN(1,(TODAY()-F9)/(G9-F9))*'設定'!$B$6,"🟡要注意","🔴遅れ"))))))) | N9: =IF($A9="","",SUMIFS('日次ログ'!$D$5:$D$1504,'日次ログ'!$B$5:$B$1504,$A9,'日次ログ'!$A$5:$A$1504,">="&(TODAY()-6))) | O9: =IF($A9="","",SUMIFS('日次ログ'!$F$5:$F$1504,'日次ログ'!$B$5:$B$1504,$A9,'日次ログ'!$A$5:$A$1504,">="&(TODAY()-6))) | P9: =IF($A9="","",IF(COUNTIF('日次ログ'!$B$5:$B$1504,$A9)=0,"",_xlfn.MAXIFS('日次ログ'!$A$5:$A$1504,'日次ログ'!$B$5:$B$1504,$A9))) | Q9: =IF($A9="","",IFERROR(COUNTIF(INDIRECT("'"&$A9&"'!E9:E21"),"承諾")&" / "&COUNTA(INDIRECT("'"&$A9&"'!B9:B21")),"")) | R9: =IF($A9="","",IFERROR(IF(INDIRECT("'"&$A9&"'!B27")="","",INDIRECT("'"&$A9&"'!B27")),"")) | S9: =IF($A9="","",IFERROR(IF(INDIRECT("'"&$A9&"'!B28")="","",INDIRECT("'"&$A9&"'!B28")),"")) | T9: =IF($A9="","",COUNTIFS('入会後行動リスト'!$B$5:$B$2004,$A9,'入会後行動リスト'!$J$5:$J$2004,"期限超過")) | U9: =IF($A9="","",COUNTIFS('CCS追っかけ'!$B$5:$B$504,$A9,'CCS追っかけ'!$J$5:$J$504,"CCS済")+COUNTIFS('CCS追っかけ'!$B$5:$B$504,$A9,'CCS追っかけ'!$P$5:$P$504,"✅正式",'CCS追っかけ'!$J$5:$J$504,"<>CCS済"))
A10: 矢野貴之 | B10: =IF($A10="","",IFERROR(IF(INDIRECT("'"&$A10&"'!B4")="","",INDIRECT("'"&$A10&"'!B4")),"")) | C10: =IF($A10="","",IFERROR(IF(INDIRECT("'"&$A10&"'!B6")="","",INDIRECT("'"&$A10&"'!B6")),"")) | D10: =IF($A10="","",IFERROR(IF(INDIRECT("'"&$A10&"'!B8")="","",INDIRECT("'"&$A10&"'!B8")),"")) | E10: =IF($A10="","",IFERROR(IF(INDIRECT("'"&$A10&"'!B24")="","",INDIRECT("'"&$A10&"'!B24")),"")) | F10: =IF($A10="","",IFERROR(IF(INDIRECT("'"&$A10&"'!B25")="","",INDIRECT("'"&$A10&"'!B25")),"")) | G10: =IF(OR($A10="",F10=""),"",IF(E10="フェーズ1",F10+'設定'!$B$4,IF(E10="フェーズ2",F10+'設定'!$B$5,""))) | H10: =IF(G10="","",G10-TODAY()) | I10: =IF($A10="","",IFERROR(IF(INDIRECT("'"&$A10&"'!B26")="","",INDIRECT("'"&$A10&"'!B26")),"")) | J10: =IF($A10="","",COUNTIFS('CCS追っかけ'!$B$5:$B$504,$A10,'CCS追っかけ'!$P$5:$P$504,"✅正式")) | K10: =IF($A10="","",COUNTIFS('CCS追っかけ'!$B$5:$B$504,$A10,'CCS追っかけ'!$D$5:$D$504,"<>",'CCS追っかけ'!$V$5:$V$504,"<>辞退")-J10) | L10: =IF(OR($A10="",I10="",I10=0),"",J10/I10) | M10: =IF(OR($A10="",I10="",F10=""),"",IF(J10>=I10,"🟢達成",IF(G10="","🟡進行中",IF(H10<0,"🔴期限超過",IF(AND(H10<='設定'!$B$7,J10<I10*0.8),"🔴期限間近",IF(J10>=I10*MIN(1,(TODAY()-F10)/(G10-F10)),"🟢順調",IF(J10>=I10*MIN(1,(TODAY()-F10)/(G10-F10))*'設定'!$B$6,"🟡要注意","🔴遅れ"))))))) | N10: =IF($A10="","",SUMIFS('日次ログ'!$D$5:$D$1504,'日次ログ'!$B$5:$B$1504,$A10,'日次ログ'!$A$5:$A$1504,">="&(TODAY()-6))) | O10: =IF($A10="","",SUMIFS('日次ログ'!$F$5:$F$1504,'日次ログ'!$B$5:$B$1504,$A10,'日次ログ'!$A$5:$A$1504,">="&(TODAY()-6))) | P10: =IF($A10="","",IF(COUNTIF('日次ログ'!$B$5:$B$1504,$A10)=0,"",_xlfn.MAXIFS('日次ログ'!$A$5:$A$1504,'日次ログ'!$B$5:$B$1504,$A10))) | Q10: =IF($A10="","",IFERROR(COUNTIF(INDIRECT("'"&$A10&"'!E9:E21"),"承諾")&" / "&COUNTA(INDIRECT("'"&$A10&"'!B9:B21")),"")) | R10: =IF($A10="","",IFERROR(IF(INDIRECT("'"&$A10&"'!B27")="","",INDIRECT("'"&$A10&"'!B27")),"")) | S10: =IF($A10="","",IFERROR(IF(INDIRECT("'"&$A10&"'!B28")="","",INDIRECT("'"&$A10&"'!B28")),"")) | T10: =IF($A10="","",COUNTIFS('入会後行動リスト'!$B$5:$B$2004,$A10,'入会後行動リスト'!$J$5:$J$2004,"期限超過")) | U10: =IF($A10="","",COUNTIFS('CCS追っかけ'!$B$5:$B$504,$A10,'CCS追っかけ'!$J$5:$J$504,"CCS済")+COUNTIFS('CCS追っかけ'!$B$5:$B$504,$A10,'CCS追っかけ'!$P$5:$P$504,"✅正式",'CCS追っかけ'!$J$5:$J$504,"<>CCS済"))
A11: 榎田秀一 | B11: =IF($A11="","",IFERROR(IF(INDIRECT("'"&$A11&"'!B4")="","",INDIRECT("'"&$A11&"'!B4")),"")) | C11: =IF($A11="","",IFERROR(IF(INDIRECT("'"&$A11&"'!B6")="","",INDIRECT("'"&$A11&"'!B6")),"")) | D11: =IF($A11="","",IFERROR(IF(INDIRECT("'"&$A11&"'!B8")="","",INDIRECT("'"&$A11&"'!B8")),"")) | E11: =IF($A11="","",IFERROR(IF(INDIRECT("'"&$A11&"'!B24")="","",INDIRECT("'"&$A11&"'!B24")),"")) | F11: =IF($A11="","",IFERROR(IF(INDIRECT("'"&$A11&"'!B25")="","",INDIRECT("'"&$A11&"'!B25")),"")) | G11: =IF(OR($A11="",F11=""),"",IF(E11="フェーズ1",F11+'設定'!$B$4,IF(E11="フェーズ2",F11+'設定'!$B$5,""))) | H11: =IF(G11="","",G11-TODAY()) | I11: =IF($A11="","",IFERROR(IF(INDIRECT("'"&$A11&"'!B26")="","",INDIRECT("'"&$A11&"'!B26")),"")) | J11: =IF($A11="","",COUNTIFS('CCS追っかけ'!$B$5:$B$504,$A11,'CCS追っかけ'!$P$5:$P$504,"✅正式")) | K11: =IF($A11="","",COUNTIFS('CCS追っかけ'!$B$5:$B$504,$A11,'CCS追っかけ'!$D$5:$D$504,"<>",'CCS追っかけ'!$V$5:$V$504,"<>辞退")-J11) | L11: =IF(OR($A11="",I11="",I11=0),"",J11/I11) | M11: =IF(OR($A11="",I11="",F11=""),"",IF(J11>=I11,"🟢達成",IF(G11="","🟡進行中",IF(H11<0,"🔴期限超過",IF(AND(H11<='設定'!$B$7,J11<I11*0.8),"🔴期限間近",IF(J11>=I11*MIN(1,(TODAY()-F11)/(G11-F11)),"🟢順調",IF(J11>=I11*MIN(1,(TODAY()-F11)/(G11-F11))*'設定'!$B$6,"🟡要注意","🔴遅れ"))))))) | N11: =IF($A11="","",SUMIFS('日次ログ'!$D$5:$D$1504,'日次ログ'!$B$5:$B$1504,$A11,'日次ログ'!$A$5:$A$1504,">="&(TODAY()-6))) | O11: =IF($A11="","",SUMIFS('日次ログ'!$F$5:$F$1504,'日次ログ'!$B$5:$B$1504,$A11,'日次ログ'!$A$5:$A$1504,">="&(TODAY()-6))) | P11: =IF($A11="","",IF(COUNTIF('日次ログ'!$B$5:$B$1504,$A11)=0,"",_xlfn.MAXIFS('日次ログ'!$A$5:$A$1504,'日次ログ'!$B$5:$B$1504,$A11))) | Q11: =IF($A11="","",IFERROR(COUNTIF(INDIRECT("'"&$A11&"'!E9:E21"),"承諾")&" / "&COUNTA(INDIRECT("'"&$A11&"'!B9:B21")),"")) | R11: =IF($A11="","",IFERROR(IF(INDIRECT("'"&$A11&"'!B27")="","",INDIRECT("'"&$A11&"'!B27")),"")) | S11: =IF($A11="","",IFERROR(IF(INDIRECT("'"&$A11&"'!B28")="","",INDIRECT("'"&$A11&"'!B28")),"")) | T11: =IF($A11="","",COUNTIFS('入会後行動リスト'!$B$5:$B$2004,$A11,'入会後行動リスト'!$J$5:$J$2004,"期限超過")) | U11: =IF($A11="","",COUNTIFS('CCS追っかけ'!$B$5:$B$504,$A11,'CCS追っかけ'!$J$5:$J$504,"CCS済")+COUNTIFS('CCS追っかけ'!$B$5:$B$504,$A11,'CCS追っかけ'!$P$5:$P$504,"✅正式",'CCS追っかけ'!$J$5:$J$504,"<>CCS済"))
A12: 世良真貴男 | B12: =IF($A12="","",IFERROR(IF(INDIRECT("'"&$A12&"'!B4")="","",INDIRECT("'"&$A12&"'!B4")),"")) | C12: =IF($A12="","",IFERROR(IF(INDIRECT("'"&$A12&"'!B6")="","",INDIRECT("'"&$A12&"'!B6")),"")) | D12: =IF($A12="","",IFERROR(IF(INDIRECT("'"&$A12&"'!B8")="","",INDIRECT("'"&$A12&"'!B8")),"")) | E12: =IF($A12="","",IFERROR(IF(INDIRECT("'"&$A12&"'!B24")="","",INDIRECT("'"&$A12&"'!B24")),"")) | F12: =IF($A12="","",IFERROR(IF(INDIRECT("'"&$A12&"'!B25")="","",INDIRECT("'"&$A12&"'!B25")),"")) | G12: =IF(OR($A12="",F12=""),"",IF(E12="フェーズ1",F12+'設定'!$B$4,IF(E12="フェーズ2",F12+'設定'!$B$5,""))) | H12: =IF(G12="","",G12-TODAY()) | I12: =IF($A12="","",IFERROR(IF(INDIRECT("'"&$A12&"'!B26")="","",INDIRECT("'"&$A12&"'!B26")),"")) | J12: =IF($A12="","",COUNTIFS('CCS追っかけ'!$B$5:$B$504,$A12,'CCS追っかけ'!$P$5:$P$504,"✅正式")) | K12: =IF($A12="","",COUNTIFS('CCS追っかけ'!$B$5:$B$504,$A12,'CCS追っかけ'!$D$5:$D$504,"<>",'CCS追っかけ'!$V$5:$V$504,"<>辞退")-J12) | L12: =IF(OR($A12="",I12="",I12=0),"",J12/I12) | M12: =IF(OR($A12="",I12="",F12=""),"",IF(J12>=I12,"🟢達成",IF(G12="","🟡進行中",IF(H12<0,"🔴期限超過",IF(AND(H12<='設定'!$B$7,J12<I12*0.8),"🔴期限間近",IF(J12>=I12*MIN(1,(TODAY()-F12)/(G12-F12)),"🟢順調",IF(J12>=I12*MIN(1,(TODAY()-F12)/(G12-F12))*'設定'!$B$6,"🟡要注意","🔴遅れ"))))))) | N12: =IF($A12="","",SUMIFS('日次ログ'!$D$5:$D$1504,'日次ログ'!$B$5:$B$1504,$A12,'日次ログ'!$A$5:$A$1504,">="&(TODAY()-6))) | O12: =IF($A12="","",SUMIFS('日次ログ'!$F$5:$F$1504,'日次ログ'!$B$5:$B$1504,$A12,'日次ログ'!$A$5:$A$1504,">="&(TODAY()-6))) | P12: =IF($A12="","",IF(COUNTIF('日次ログ'!$B$5:$B$1504,$A12)=0,"",_xlfn.MAXIFS('日次ログ'!$A$5:$A$1504,'日次ログ'!$B$5:$B$1504,$A12))) | Q12: =IF($A12="","",IFERROR(COUNTIF(INDIRECT("'"&$A12&"'!E9:E21"),"承諾")&" / "&COUNTA(INDIRECT("'"&$A12&"'!B9:B21")),"")) | R12: =IF($A12="","",IFERROR(IF(INDIRECT("'"&$A12&"'!B27")="","",INDIRECT("'"&$A12&"'!B27")),"")) | S12: =IF($A12="","",IFERROR(IF(INDIRECT("'"&$A12&"'!B28")="","",INDIRECT("'"&$A12&"'!B28")),"")) | T12: =IF($A12="","",COUNTIFS('入会後行動リスト'!$B$5:$B$2004,$A12,'入会後行動リスト'!$J$5:$J$2004,"期限超過")) | U12: =IF($A12="","",COUNTIFS('CCS追っかけ'!$B$5:$B$504,$A12,'CCS追っかけ'!$J$5:$J$504,"CCS済")+COUNTIFS('CCS追っかけ'!$B$5:$B$504,$A12,'CCS追っかけ'!$P$5:$P$504,"✅正式",'CCS追っかけ'!$J$5:$J$504,"<>CCS済"))
A13: 松永健志 | B13: =IF($A13="","",IFERROR(IF(INDIRECT("'"&$A13&"'!B4")="","",INDIRECT("'"&$A13&"'!B4")),"")) | C13: =IF($A13="","",IFERROR(IF(INDIRECT("'"&$A13&"'!B6")="","",INDIRECT("'"&$A13&"'!B6")),"")) | D13: =IF($A13="","",IFERROR(IF(INDIRECT("'"&$A13&"'!B8")="","",INDIRECT("'"&$A13&"'!B8")),"")) | E13: =IF($A13="","",IFERROR(IF(INDIRECT("'"&$A13&"'!B24")="","",INDIRECT("'"&$A13&"'!B24")),"")) | F13: =IF($A13="","",IFERROR(IF(INDIRECT("'"&$A13&"'!B25")="","",INDIRECT("'"&$A13&"'!B25")),"")) | G13: =IF(OR($A13="",F13=""),"",IF(E13="フェーズ1",F13+'設定'!$B$4,IF(E13="フェーズ2",F13+'設定'!$B$5,""))) | H13: =IF(G13="","",G13-TODAY()) | I13: =IF($A13="","",IFERROR(IF(INDIRECT("'"&$A13&"'!B26")="","",INDIRECT("'"&$A13&"'!B26")),"")) | J13: =IF($A13="","",COUNTIFS('CCS追っかけ'!$B$5:$B$504,$A13,'CCS追っかけ'!$P$5:$P$504,"✅正式")) | K13: =IF($A13="","",COUNTIFS('CCS追っかけ'!$B$5:$B$504,$A13,'CCS追っかけ'!$D$5:$D$504,"<>",'CCS追っかけ'!$V$5:$V$504,"<>辞退")-J13) | L13: =IF(OR($A13="",I13="",I13=0),"",J13/I13) | M13: =IF(OR($A13="",I13="",F13=""),"",IF(J13>=I13,"🟢達成",IF(G13="","🟡進行中",IF(H13<0,"🔴期限超過",IF(AND(H13<='設定'!$B$7,J13<I13*0.8),"🔴期限間近",IF(J13>=I13*MIN(1,(TODAY()-F13)/(G13-F13)),"🟢順調",IF(J13>=I13*MIN(1,(TODAY()-F13)/(G13-F13))*'設定'!$B$6,"🟡要注意","🔴遅れ"))))))) | N13: =IF($A13="","",SUMIFS('日次ログ'!$D$5:$D$1504,'日次ログ'!$B$5:$B$1504,$A13,'日次ログ'!$A$5:$A$1504,">="&(TODAY()-6))) | O13: =IF($A13="","",SUMIFS('日次ログ'!$F$5:$F$1504,'日次ログ'!$B$5:$B$1504,$A13,'日次ログ'!$A$5:$A$1504,">="&(TODAY()-6))) | P13: =IF($A13="","",IF(COUNTIF('日次ログ'!$B$5:$B$1504,$A13)=0,"",_xlfn.MAXIFS('日次ログ'!$A$5:$A$1504,'日次ログ'!$B$5:$B$1504,$A13))) | Q13: =IF($A13="","",IFERROR(COUNTIF(INDIRECT("'"&$A13&"'!E9:E21"),"承諾")&" / "&COUNTA(INDIRECT("'"&$A13&"'!B9:B21")),"")) | R13: =IF($A13="","",IFERROR(IF(INDIRECT("'"&$A13&"'!B27")="","",INDIRECT("'"&$A13&"'!B27")),"")) | S13: =IF($A13="","",IFERROR(IF(INDIRECT("'"&$A13&"'!B28")="","",INDIRECT("'"&$A13&"'!B28")),"")) | T13: =IF($A13="","",COUNTIFS('入会後行動リスト'!$B$5:$B$2004,$A13,'入会後行動リスト'!$J$5:$J$2004,"期限超過")) | U13: =IF($A13="","",COUNTIFS('CCS追っかけ'!$B$5:$B$504,$A13,'CCS追っかけ'!$J$5:$J$504,"CCS済")+COUNTIFS('CCS追っかけ'!$B$5:$B$504,$A13,'CCS追っかけ'!$P$5:$P$504,"✅正式",'CCS追っかけ'!$J$5:$J$504,"<>CCS済"))
A14: 中村剛 | B14: =IF($A14="","",IFERROR(IF(INDIRECT("'"&$A14&"'!B4")="","",INDIRECT("'"&$A14&"'!B4")),"")) | C14: =IF($A14="","",IFERROR(IF(INDIRECT("'"&$A14&"'!B6")="","",INDIRECT("'"&$A14&"'!B6")),"")) | D14: =IF($A14="","",IFERROR(IF(INDIRECT("'"&$A14&"'!B8")="","",INDIRECT("'"&$A14&"'!B8")),"")) | E14: =IF($A14="","",IFERROR(IF(INDIRECT("'"&$A14&"'!B24")="","",INDIRECT("'"&$A14&"'!B24")),"")) | F14: =IF($A14="","",IFERROR(IF(INDIRECT("'"&$A14&"'!B25")="","",INDIRECT("'"&$A14&"'!B25")),"")) | G14: =IF(OR($A14="",F14=""),"",IF(E14="フェーズ1",F14+'設定'!$B$4,IF(E14="フェーズ2",F14+'設定'!$B$5,""))) | H14: =IF(G14="","",G14-TODAY()) | I14: =IF($A14="","",IFERROR(IF(INDIRECT("'"&$A14&"'!B26")="","",INDIRECT("'"&$A14&"'!B26")),"")) | J14: =IF($A14="","",COUNTIFS('CCS追っかけ'!$B$5:$B$504,$A14,'CCS追っかけ'!$P$5:$P$504,"✅正式")) | K14: =IF($A14="","",COUNTIFS('CCS追っかけ'!$B$5:$B$504,$A14,'CCS追っかけ'!$D$5:$D$504,"<>",'CCS追っかけ'!$V$5:$V$504,"<>辞退")-J14) | L14: =IF(OR($A14="",I14="",I14=0),"",J14/I14) | M14: =IF(OR($A14="",I14="",F14=""),"",IF(J14>=I14,"🟢達成",IF(G14="","🟡進行中",IF(H14<0,"🔴期限超過",IF(AND(H14<='設定'!$B$7,J14<I14*0.8),"🔴期限間近",IF(J14>=I14*MIN(1,(TODAY()-F14)/(G14-F14)),"🟢順調",IF(J14>=I14*MIN(1,(TODAY()-F14)/(G14-F14))*'設定'!$B$6,"🟡要注意","🔴遅れ"))))))) | N14: =IF($A14="","",SUMIFS('日次ログ'!$D$5:$D$1504,'日次ログ'!$B$5:$B$1504,$A14,'日次ログ'!$A$5:$A$1504,">="&(TODAY()-6))) | O14: =IF($A14="","",SUMIFS('日次ログ'!$F$5:$F$1504,'日次ログ'!$B$5:$B$1504,$A14,'日次ログ'!$A$5:$A$1504,">="&(TODAY()-6))) | P14: =IF($A14="","",IF(COUNTIF('日次ログ'!$B$5:$B$1504,$A14)=0,"",_xlfn.MAXIFS('日次ログ'!$A$5:$A$1504,'日次ログ'!$B$5:$B$1504,$A14))) | Q14: =IF($A14="","",IFERROR(COUNTIF(INDIRECT("'"&$A14&"'!E9:E21"),"承諾")&" / "&COUNTA(INDIRECT("'"&$A14&"'!B9:B21")),"")) | R14: =IF($A14="","",IFERROR(IF(INDIRECT("'"&$A14&"'!B27")="","",INDIRECT("'"&$A14&"'!B27")),"")) | S14: =IF($A14="","",IFERROR(IF(INDIRECT("'"&$A14&"'!B28")="","",INDIRECT("'"&$A14&"'!B28")),"")) | T14: =IF($A14="","",COUNTIFS('入会後行動リスト'!$B$5:$B$2004,$A14,'入会後行動リスト'!$J$5:$J$2004,"期限超過")) | U14: =IF($A14="","",COUNTIFS('CCS追っかけ'!$B$5:$B$504,$A14,'CCS追っかけ'!$J$5:$J$504,"CCS済")+COUNTIFS('CCS追っかけ'!$B$5:$B$504,$A14,'CCS追っかけ'!$P$5:$P$504,"✅正式",'CCS追っかけ'!$J$5:$J$504,"<>CCS済"))
B15: =IF($A15="","",IFERROR(IF(INDIRECT("'"&$A15&"'!B4")="","",INDIRECT("'"&$A15&"'!B4")),"")) | C15: =IF($A15="","",IFERROR(IF(INDIRECT("'"&$A15&"'!B6")="","",INDIRECT("'"&$A15&"'!B6")),"")) | D15: =IF($A15="","",IFERROR(IF(INDIRECT("'"&$A15&"'!B8")="","",INDIRECT("'"&$A15&"'!B8")),"")) | E15: =IF($A15="","",IFERROR(IF(INDIRECT("'"&$A15&"'!B24")="","",INDIRECT("'"&$A15&"'!B24")),"")) | F15: =IF($A15="","",IFERROR(IF(INDIRECT("'"&$A15&"'!B25")="","",INDIRECT("'"&$A15&"'!B25")),"")) | G15: =IF(OR($A15="",F15=""),"",IF(E15="フェーズ1",F15+'設定'!$B$4,IF(E15="フェーズ2",F15+'設定'!$B$5,""))) | H15: =IF(G15="","",G15-TODAY()) | I15: =IF($A15="","",IFERROR(IF(INDIRECT("'"&$A15&"'!B26")="","",INDIRECT("'"&$A15&"'!B26")),"")) | J15: =IF($A15="","",COUNTIFS('CCS追っかけ'!$B$5:$B$504,$A15,'CCS追っかけ'!$P$5:$P$504,"✅正式")) | K15: =IF($A15="","",COUNTIFS('CCS追っかけ'!$B$5:$B$504,$A15,'CCS追っかけ'!$D$5:$D$504,"<>",'CCS追っかけ'!$V$5:$V$504,"<>辞退")-J15) | L15: =IF(OR($A15="",I15="",I15=0),"",J15/I15) | M15: =IF(OR($A15="",I15="",F15=""),"",IF(J15>=I15,"🟢達成",IF(G15="","🟡進行中",IF(H15<0,"🔴期限超過",IF(AND(H15<='設定'!$B$7,J15<I15*0.8),"🔴期限間近",IF(J15>=I15*MIN(1,(TODAY()-F15)/(G15-F15)),"🟢順調",IF(J15>=I15*MIN(1,(TODAY()-F15)/(G15-F15))*'設定'!$B$6,"🟡要注意","🔴遅れ"))))))) | N15: =IF($A15="","",SUMIFS('日次ログ'!$D$5:$D$1504,'日次ログ'!$B$5:$B$1504,$A15,'日次ログ'!$A$5:$A$1504,">="&(TODAY()-6))) | O15: =IF($A15="","",SUMIFS('日次ログ'!$F$5:$F$1504,'日次ログ'!$B$5:$B$1504,$A15,'日次ログ'!$A$5:$A$1504,">="&(TODAY()-6))) | P15: =IF($A15="","",IF(COUNTIF('日次ログ'!$B$5:$B$1504,$A15)=0,"",_xlfn.MAXIFS('日次ログ'!$A$5:$A$1504,'日次ログ'!$B$5:$B$1504,$A15))) | Q15: =IF($A15="","",IFERROR(COUNTIF(INDIRECT("'"&$A15&"'!E9:E21"),"承諾")&" / "&COUNTA(INDIRECT("'"&$A15&"'!B9:B21")),"")) | R15: =IF($A15="","",IFERROR(IF(INDIRECT("'"&$A15&"'!B27")="","",INDIRECT("'"&$A15&"'!B27")),"")) | S15: =IF($A15="","",IFERROR(IF(INDIRECT("'"&$A15&"'!B28")="","",INDIRECT("'"&$A15&"'!B28")),"")) | T15: =IF($A15="","",COUNTIFS('入会後行動リスト'!$B$5:$B$2004,$A15,'入会後行動リスト'!$J$5:$J$2004,"期限超過")) | U15: =IF($A15="","",COUNTIFS('CCS追っかけ'!$B$5:$B$504,$A15,'CCS追っかけ'!$J$5:$J$504,"CCS済")+COUNTIFS('CCS追っかけ'!$B$5:$B$504,$A15,'CCS追っかけ'!$P$5:$P$504,"✅正式",'CCS追っかけ'!$J$5:$J$504,"<>CCS済"))
B16: =IF($A16="","",IFERROR(IF(INDIRECT("'"&$A16&"'!B4")="","",INDIRECT("'"&$A16&"'!B4")),"")) | C16: =IF($A16="","",IFERROR(IF(INDIRECT("'"&$A16&"'!B6")="","",INDIRECT("'"&$A16&"'!B6")),"")) | D16: =IF($A16="","",IFERROR(IF(INDIRECT("'"&$A16&"'!B8")="","",INDIRECT("'"&$A16&"'!B8")),"")) | E16: =IF($A16="","",IFERROR(IF(INDIRECT("'"&$A16&"'!B24")="","",INDIRECT("'"&$A16&"'!B24")),"")) | F16: =IF($A16="","",IFERROR(IF(INDIRECT("'"&$A16&"'!B25")="","",INDIRECT("'"&$A16&"'!B25")),"")) | G16: =IF(OR($A16="",F16=""),"",IF(E16="フェーズ1",F16+'設定'!$B$4,IF(E16="フェーズ2",F16+'設定'!$B$5,""))) | H16: =IF(G16="","",G16-TODAY()) | I16: =IF($A16="","",IFERROR(IF(INDIRECT("'"&$A16&"'!B26")="","",INDIRECT("'"&$A16&"'!B26")),"")) | J16: =IF($A16="","",COUNTIFS('CCS追っかけ'!$B$5:$B$504,$A16,'CCS追っかけ'!$P$5:$P$504,"✅正式")) | K16: =IF($A16="","",COUNTIFS('CCS追っかけ'!$B$5:$B$504,$A16,'CCS追っかけ'!$D$5:$D$504,"<>",'CCS追っかけ'!$V$5:$V$504,"<>辞退")-J16) | L16: =IF(OR($A16="",I16="",I16=0),"",J16/I16) | M16: =IF(OR($A16="",I16="",F16=""),"",IF(J16>=I16,"🟢達成",IF(G16="","🟡進行中",IF(H16<0,"🔴期限超過",IF(AND(H16<='設定'!$B$7,J16<I16*0.8),"🔴期限間近",IF(J16>=I16*MIN(1,(TODAY()-F16)/(G16-F16)),"🟢順調",IF(J16>=I16*MIN(1,(TODAY()-F16)/(G16-F16))*'設定'!$B$6,"🟡要注意","🔴遅れ"))))))) | N16: =IF($A16="","",SUMIFS('日次ログ'!$D$5:$D$1504,'日次ログ'!$B$5:$B$1504,$A16,'日次ログ'!$A$5:$A$1504,">="&(TODAY()-6))) | O16: =IF($A16="","",SUMIFS('日次ログ'!$F$5:$F$1504,'日次ログ'!$B$5:$B$1504,$A16,'日次ログ'!$A$5:$A$1504,">="&(TODAY()-6))) | P16: =IF($A16="","",IF(COUNTIF('日次ログ'!$B$5:$B$1504,$A16)=0,"",_xlfn.MAXIFS('日次ログ'!$A$5:$A$1504,'日次ログ'!$B$5:$B$1504,$A16))) | Q16: =IF($A16="","",IFERROR(COUNTIF(INDIRECT("'"&$A16&"'!E9:E21"),"承諾")&" / "&COUNTA(INDIRECT("'"&$A16&"'!B9:B21")),"")) | R16: =IF($A16="","",IFERROR(IF(INDIRECT("'"&$A16&"'!B27")="","",INDIRECT("'"&$A16&"'!B27")),"")) | S16: =IF($A16="","",IFERROR(IF(INDIRECT("'"&$A16&"'!B28")="","",INDIRECT("'"&$A16&"'!B28")),"")) | T16: =IF($A16="","",COUNTIFS('入会後行動リスト'!$B$5:$B$2004,$A16,'入会後行動リスト'!$J$5:$J$2004,"期限超過")) | U16: =IF($A16="","",COUNTIFS('CCS追っかけ'!$B$5:$B$504,$A16,'CCS追っかけ'!$J$5:$J$504,"CCS済")+COUNTIFS('CCS追っかけ'!$B$5:$B$504,$A16,'CCS追っかけ'!$P$5:$P$504,"✅正式",'CCS追っかけ'!$J$5:$J$504,"<>CCS済"))
B17: =IF($A17="","",IFERROR(IF(INDIRECT("'"&$A17&"'!B4")="","",INDIRECT("'"&$A17&"'!B4")),"")) | C17: =IF($A17="","",IFERROR(IF(INDIRECT("'"&$A17&"'!B6")="","",INDIRECT("'"&$A17&"'!B6")),"")) | D17: =IF($A17="","",IFERROR(IF(INDIRECT("'"&$A17&"'!B8")="","",INDIRECT("'"&$A17&"'!B8")),"")) | E17: =IF($A17="","",IFERROR(IF(INDIRECT("'"&$A17&"'!B24")="","",INDIRECT("'"&$A17&"'!B24")),"")) | F17: =IF($A17="","",IFERROR(IF(INDIRECT("'"&$A17&"'!B25")="","",INDIRECT("'"&$A17&"'!B25")),"")) | G17: =IF(OR($A17="",F17=""),"",IF(E17="フェーズ1",F17+'設定'!$B$4,IF(E17="フェーズ2",F17+'設定'!$B$5,""))) | H17: =IF(G17="","",G17-TODAY()) | I17: =IF($A17="","",IFERROR(IF(INDIRECT("'"&$A17&"'!B26")="","",INDIRECT("'"&$A17&"'!B26")),"")) | J17: =IF($A17="","",COUNTIFS('CCS追っかけ'!$B$5:$B$504,$A17,'CCS追っかけ'!$P$5:$P$504,"✅正式")) | K17: =IF($A17="","",COUNTIFS('CCS追っかけ'!$B$5:$B$504,$A17,'CCS追っかけ'!$D$5:$D$504,"<>",'CCS追っかけ'!$V$5:$V$504,"<>辞退")-J17) | L17: =IF(OR($A17="",I17="",I17=0),"",J17/I17) | M17: =IF(OR($A17="",I17="",F17=""),"",IF(J17>=I17,"🟢達成",IF(G17="","🟡進行中",IF(H17<0,"🔴期限超過",IF(AND(H17<='設定'!$B$7,J17<I17*0.8),"🔴期限間近",IF(J17>=I17*MIN(1,(TODAY()-F17)/(G17-F17)),"🟢順調",IF(J17>=I17*MIN(1,(TODAY()-F17)/(G17-F17))*'設定'!$B$6,"🟡要注意","🔴遅れ"))))))) | N17: =IF($A17="","",SUMIFS('日次ログ'!$D$5:$D$1504,'日次ログ'!$B$5:$B$1504,$A17,'日次ログ'!$A$5:$A$1504,">="&(TODAY()-6))) | O17: =IF($A17="","",SUMIFS('日次ログ'!$F$5:$F$1504,'日次ログ'!$B$5:$B$1504,$A17,'日次ログ'!$A$5:$A$1504,">="&(TODAY()-6))) | P17: =IF($A17="","",IF(COUNTIF('日次ログ'!$B$5:$B$1504,$A17)=0,"",_xlfn.MAXIFS('日次ログ'!$A$5:$A$1504,'日次ログ'!$B$5:$B$1504,$A17))) | Q17: =IF($A17="","",IFERROR(COUNTIF(INDIRECT("'"&$A17&"'!E9:E21"),"承諾")&" / "&COUNTA(INDIRECT("'"&$A17&"'!B9:B21")),"")) | R17: =IF($A17="","",IFERROR(IF(INDIRECT("'"&$A17&"'!B27")="","",INDIRECT("'"&$A17&"'!B27")),"")) | S17: =IF($A17="","",IFERROR(IF(INDIRECT("'"&$A17&"'!B28")="","",INDIRECT("'"&$A17&"'!B28")),"")) | T17: =IF($A17="","",COUNTIFS('入会後行動リスト'!$B$5:$B$2004,$A17,'入会後行動リスト'!$J$5:$J$2004,"期限超過")) | U17: =IF($A17="","",COUNTIFS('CCS追っかけ'!$B$5:$B$504,$A17,'CCS追っかけ'!$J$5:$J$504,"CCS済")+COUNTIFS('CCS追っかけ'!$B$5:$B$504,$A17,'CCS追っかけ'!$P$5:$P$504,"✅正式",'CCS追っかけ'!$J$5:$J$504,"<>CCS済"))
B18: =IF($A18="","",IFERROR(IF(INDIRECT("'"&$A18&"'!B4")="","",INDIRECT("'"&$A18&"'!B4")),"")) | C18: =IF($A18="","",IFERROR(IF(INDIRECT("'"&$A18&"'!B6")="","",INDIRECT("'"&$A18&"'!B6")),"")) | D18: =IF($A18="","",IFERROR(IF(INDIRECT("'"&$A18&"'!B8")="","",INDIRECT("'"&$A18&"'!B8")),"")) | E18: =IF($A18="","",IFERROR(IF(INDIRECT("'"&$A18&"'!B24")="","",INDIRECT("'"&$A18&"'!B24")),"")) | F18: =IF($A18="","",IFERROR(IF(INDIRECT("'"&$A18&"'!B25")="","",INDIRECT("'"&$A18&"'!B25")),"")) | G18: =IF(OR($A18="",F18=""),"",IF(E18="フェーズ1",F18+'設定'!$B$4,IF(E18="フェーズ2",F18+'設定'!$B$5,""))) | H18: =IF(G18="","",G18-TODAY()) | I18: =IF($A18="","",IFERROR(IF(INDIRECT("'"&$A18&"'!B26")="","",INDIRECT("'"&$A18&"'!B26")),"")) | J18: =IF($A18="","",COUNTIFS('CCS追っかけ'!$B$5:$B$504,$A18,'CCS追っかけ'!$P$5:$P$504,"✅正式")) | K18: =IF($A18="","",COUNTIFS('CCS追っかけ'!$B$5:$B$504,$A18,'CCS追っかけ'!$D$5:$D$504,"<>",'CCS追っかけ'!$V$5:$V$504,"<>辞退")-J18) | L18: =IF(OR($A18="",I18="",I18=0),"",J18/I18) | M18: =IF(OR($A18="",I18="",F18=""),"",IF(J18>=I18,"🟢達成",IF(G18="","🟡進行中",IF(H18<0,"🔴期限超過",IF(AND(H18<='設定'!$B$7,J18<I18*0.8),"🔴期限間近",IF(J18>=I18*MIN(1,(TODAY()-F18)/(G18-F18)),"🟢順調",IF(J18>=I18*MIN(1,(TODAY()-F18)/(G18-F18))*'設定'!$B$6,"🟡要注意","🔴遅れ"))))))) | N18: =IF($A18="","",SUMIFS('日次ログ'!$D$5:$D$1504,'日次ログ'!$B$5:$B$1504,$A18,'日次ログ'!$A$5:$A$1504,">="&(TODAY()-6))) | O18: =IF($A18="","",SUMIFS('日次ログ'!$F$5:$F$1504,'日次ログ'!$B$5:$B$1504,$A18,'日次ログ'!$A$5:$A$1504,">="&(TODAY()-6))) | P18: =IF($A18="","",IF(COUNTIF('日次ログ'!$B$5:$B$1504,$A18)=0,"",_xlfn.MAXIFS('日次ログ'!$A$5:$A$1504,'日次ログ'!$B$5:$B$1504,$A18))) | Q18: =IF($A18="","",IFERROR(COUNTIF(INDIRECT("'"&$A18&"'!E9:E21"),"承諾")&" / "&COUNTA(INDIRECT("'"&$A18&"'!B9:B21")),"")) | R18: =IF($A18="","",IFERROR(IF(INDIRECT("'"&$A18&"'!B27")="","",INDIRECT("'"&$A18&"'!B27")),"")) | S18: =IF($A18="","",IFERROR(IF(INDIRECT("'"&$A18&"'!B28")="","",INDIRECT("'"&$A18&"'!B28")),"")) | T18: =IF($A18="","",COUNTIFS('入会後行動リスト'!$B$5:$B$2004,$A18,'入会後行動リスト'!$J$5:$J$2004,"期限超過")) | U18: =IF($A18="","",COUNTIFS('CCS追っかけ'!$B$5:$B$504,$A18,'CCS追っかけ'!$J$5:$J$504,"CCS済")+COUNTIFS('CCS追っかけ'!$B$5:$B$504,$A18,'CCS追っかけ'!$P$5:$P$504,"✅正式",'CCS追っかけ'!$J$5:$J$504,"<>CCS済"))
B19: =IF($A19="","",IFERROR(IF(INDIRECT("'"&$A19&"'!B4")="","",INDIRECT("'"&$A19&"'!B4")),"")) | C19: =IF($A19="","",IFERROR(IF(INDIRECT("'"&$A19&"'!B6")="","",INDIRECT("'"&$A19&"'!B6")),"")) | D19: =IF($A19="","",IFERROR(IF(INDIRECT("'"&$A19&"'!B8")="","",INDIRECT("'"&$A19&"'!B8")),"")) | E19: =IF($A19="","",IFERROR(IF(INDIRECT("'"&$A19&"'!B24")="","",INDIRECT("'"&$A19&"'!B24")),"")) | F19: =IF($A19="","",IFERROR(IF(INDIRECT("'"&$A19&"'!B25")="","",INDIRECT("'"&$A19&"'!B25")),"")) | G19: =IF(OR($A19="",F19=""),"",IF(E19="フェーズ1",F19+'設定'!$B$4,IF(E19="フェーズ2",F19+'設定'!$B$5,""))) | H19: =IF(G19="","",G19-TODAY()) | I19: =IF($A19="","",IFERROR(IF(INDIRECT("'"&$A19&"'!B26")="","",INDIRECT("'"&$A19&"'!B26")),"")) | J19: =IF($A19="","",COUNTIFS('CCS追っかけ'!$B$5:$B$504,$A19,'CCS追っかけ'!$P$5:$P$504,"✅正式")) | K19: =IF($A19="","",COUNTIFS('CCS追っかけ'!$B$5:$B$504,$A19,'CCS追っかけ'!$D$5:$D$504,"<>",'CCS追っかけ'!$V$5:$V$504,"<>辞退")-J19) | L19: =IF(OR($A19="",I19="",I19=0),"",J19/I19) | M19: =IF(OR($A19="",I19="",F19=""),"",IF(J19>=I19,"🟢達成",IF(G19="","🟡進行中",IF(H19<0,"🔴期限超過",IF(AND(H19<='設定'!$B$7,J19<I19*0.8),"🔴期限間近",IF(J19>=I19*MIN(1,(TODAY()-F19)/(G19-F19)),"🟢順調",IF(J19>=I19*MIN(1,(TODAY()-F19)/(G19-F19))*'設定'!$B$6,"🟡要注意","🔴遅れ"))))))) | N19: =IF($A19="","",SUMIFS('日次ログ'!$D$5:$D$1504,'日次ログ'!$B$5:$B$1504,$A19,'日次ログ'!$A$5:$A$1504,">="&(TODAY()-6))) | O19: =IF($A19="","",SUMIFS('日次ログ'!$F$5:$F$1504,'日次ログ'!$B$5:$B$1504,$A19,'日次ログ'!$A$5:$A$1504,">="&(TODAY()-6))) | P19: =IF($A19="","",IF(COUNTIF('日次ログ'!$B$5:$B$1504,$A19)=0,"",_xlfn.MAXIFS('日次ログ'!$A$5:$A$1504,'日次ログ'!$B$5:$B$1504,$A19))) | Q19: =IF($A19="","",IFERROR(COUNTIF(INDIRECT("'"&$A19&"'!E9:E21"),"承諾")&" / "&COUNTA(INDIRECT("'"&$A19&"'!B9:B21")),"")) | R19: =IF($A19="","",IFERROR(IF(INDIRECT("'"&$A19&"'!B27")="","",INDIRECT("'"&$A19&"'!B27")),"")) | S19: =IF($A19="","",IFERROR(IF(INDIRECT("'"&$A19&"'!B28")="","",INDIRECT("'"&$A19&"'!B28")),"")) | T19: =IF($A19="","",COUNTIFS('入会後行動リスト'!$B$5:$B$2004,$A19,'入会後行動リスト'!$J$5:$J$2004,"期限超過")) | U19: =IF($A19="","",COUNTIFS('CCS追っかけ'!$B$5:$B$504,$A19,'CCS追っかけ'!$J$5:$J$504,"CCS済")+COUNTIFS('CCS追っかけ'!$B$5:$B$504,$A19,'CCS追っかけ'!$P$5:$P$504,"✅正式",'CCS追っかけ'!$J$5:$J$504,"<>CCS済"))
B20: =IF($A20="","",IFERROR(IF(INDIRECT("'"&$A20&"'!B4")="","",INDIRECT("'"&$A20&"'!B4")),"")) | C20: =IF($A20="","",IFERROR(IF(INDIRECT("'"&$A20&"'!B6")="","",INDIRECT("'"&$A20&"'!B6")),"")) | D20: =IF($A20="","",IFERROR(IF(INDIRECT("'"&$A20&"'!B8")="","",INDIRECT("'"&$A20&"'!B8")),"")) | E20: =IF($A20="","",IFERROR(IF(INDIRECT("'"&$A20&"'!B24")="","",INDIRECT("'"&$A20&"'!B24")),"")) | F20: =IF($A20="","",IFERROR(IF(INDIRECT("'"&$A20&"'!B25")="","",INDIRECT("'"&$A20&"'!B25")),"")) | G20: =IF(OR($A20="",F20=""),"",IF(E20="フェーズ1",F20+'設定'!$B$4,IF(E20="フェーズ2",F20+'設定'!$B$5,""))) | H20: =IF(G20="","",G20-TODAY()) | I20: =IF($A20="","",IFERROR(IF(INDIRECT("'"&$A20&"'!B26")="","",INDIRECT("'"&$A20&"'!B26")),"")) | J20: =IF($A20="","",COUNTIFS('CCS追っかけ'!$B$5:$B$504,$A20,'CCS追っかけ'!$P$5:$P$504,"✅正式")) | K20: =IF($A20="","",COUNTIFS('CCS追っかけ'!$B$5:$B$504,$A20,'CCS追っかけ'!$D$5:$D$504,"<>",'CCS追っかけ'!$V$5:$V$504,"<>辞退")-J20) | L20: =IF(OR($A20="",I20="",I20=0),"",J20/I20) | M20: =IF(OR($A20="",I20="",F20=""),"",IF(J20>=I20,"🟢達成",IF(G20="","🟡進行中",IF(H20<0,"🔴期限超過",IF(AND(H20<='設定'!$B$7,J20<I20*0.8),"🔴期限間近",IF(J20>=I20*MIN(1,(TODAY()-F20)/(G20-F20)),"🟢順調",IF(J20>=I20*MIN(1,(TODAY()-F20)/(G20-F20))*'設定'!$B$6,"🟡要注意","🔴遅れ"))))))) | N20: =IF($A20="","",SUMIFS('日次ログ'!$D$5:$D$1504,'日次ログ'!$B$5:$B$1504,$A20,'日次ログ'!$A$5:$A$1504,">="&(TODAY()-6))) | O20: =IF($A20="","",SUMIFS('日次ログ'!$F$5:$F$1504,'日次ログ'!$B$5:$B$1504,$A20,'日次ログ'!$A$5:$A$1504,">="&(TODAY()-6))) | P20: =IF($A20="","",IF(COUNTIF('日次ログ'!$B$5:$B$1504,$A20)=0,"",_xlfn.MAXIFS('日次ログ'!$A$5:$A$1504,'日次ログ'!$B$5:$B$1504,$A20))) | Q20: =IF($A20="","",IFERROR(COUNTIF(INDIRECT("'"&$A20&"'!E9:E21"),"承諾")&" / "&COUNTA(INDIRECT("'"&$A20&"'!B9:B21")),"")) | R20: =IF($A20="","",IFERROR(IF(INDIRECT("'"&$A20&"'!B27")="","",INDIRECT("'"&$A20&"'!B27")),"")) | S20: =IF($A20="","",IFERROR(IF(INDIRECT("'"&$A20&"'!B28")="","",INDIRECT("'"&$A20&"'!B28")),"")) | T20: =IF($A20="","",COUNTIFS('入会後行動リスト'!$B$5:$B$2004,$A20,'入会後行動リスト'!$J$5:$J$2004,"期限超過")) | U20: =IF($A20="","",COUNTIFS('CCS追っかけ'!$B$5:$B$504,$A20,'CCS追っかけ'!$J$5:$J$504,"CCS済")+COUNTIFS('CCS追っかけ'!$B$5:$B$504,$A20,'CCS追っかけ'!$P$5:$P$504,"✅正式",'CCS追っかけ'!$J$5:$J$504,"<>CCS済"))
B21: =IF($A21="","",IFERROR(IF(INDIRECT("'"&$A21&"'!B4")="","",INDIRECT("'"&$A21&"'!B4")),"")) | C21: =IF($A21="","",IFERROR(IF(INDIRECT("'"&$A21&"'!B6")="","",INDIRECT("'"&$A21&"'!B6")),"")) | D21: =IF($A21="","",IFERROR(IF(INDIRECT("'"&$A21&"'!B8")="","",INDIRECT("'"&$A21&"'!B8")),"")) | E21: =IF($A21="","",IFERROR(IF(INDIRECT("'"&$A21&"'!B24")="","",INDIRECT("'"&$A21&"'!B24")),"")) | F21: =IF($A21="","",IFERROR(IF(INDIRECT("'"&$A21&"'!B25")="","",INDIRECT("'"&$A21&"'!B25")),"")) | G21: =IF(OR($A21="",F21=""),"",IF(E21="フェーズ1",F21+'設定'!$B$4,IF(E21="フェーズ2",F21+'設定'!$B$5,""))) | H21: =IF(G21="","",G21-TODAY()) | I21: =IF($A21="","",IFERROR(IF(INDIRECT("'"&$A21&"'!B26")="","",INDIRECT("'"&$A21&"'!B26")),"")) | J21: =IF($A21="","",COUNTIFS('CCS追っかけ'!$B$5:$B$504,$A21,'CCS追っかけ'!$P$5:$P$504,"✅正式")) | K21: =IF($A21="","",COUNTIFS('CCS追っかけ'!$B$5:$B$504,$A21,'CCS追っかけ'!$D$5:$D$504,"<>",'CCS追っかけ'!$V$5:$V$504,"<>辞退")-J21) | L21: =IF(OR($A21="",I21="",I21=0),"",J21/I21) | M21: =IF(OR($A21="",I21="",F21=""),"",IF(J21>=I21,"🟢達成",IF(G21="","🟡進行中",IF(H21<0,"🔴期限超過",IF(AND(H21<='設定'!$B$7,J21<I21*0.8),"🔴期限間近",IF(J21>=I21*MIN(1,(TODAY()-F21)/(G21-F21)),"🟢順調",IF(J21>=I21*MIN(1,(TODAY()-F21)/(G21-F21))*'設定'!$B$6,"🟡要注意","🔴遅れ"))))))) | N21: =IF($A21="","",SUMIFS('日次ログ'!$D$5:$D$1504,'日次ログ'!$B$5:$B$1504,$A21,'日次ログ'!$A$5:$A$1504,">="&(TODAY()-6))) | O21: =IF($A21="","",SUMIFS('日次ログ'!$F$5:$F$1504,'日次ログ'!$B$5:$B$1504,$A21,'日次ログ'!$A$5:$A$1504,">="&(TODAY()-6))) | P21: =IF($A21="","",IF(COUNTIF('日次ログ'!$B$5:$B$1504,$A21)=0,"",_xlfn.MAXIFS('日次ログ'!$A$5:$A$1504,'日次ログ'!$B$5:$B$1504,$A21))) | Q21: =IF($A21="","",IFERROR(COUNTIF(INDIRECT("'"&$A21&"'!E9:E21"),"承諾")&" / "&COUNTA(INDIRECT("'"&$A21&"'!B9:B21")),"")) | R21: =IF($A21="","",IFERROR(IF(INDIRECT("'"&$A21&"'!B27")="","",INDIRECT("'"&$A21&"'!B27")),"")) | S21: =IF($A21="","",IFERROR(IF(INDIRECT("'"&$A21&"'!B28")="","",INDIRECT("'"&$A21&"'!B28")),"")) | T21: =IF($A21="","",COUNTIFS('入会後行動リスト'!$B$5:$B$2004,$A21,'入会後行動リスト'!$J$5:$J$2004,"期限超過")) | U21: =IF($A21="","",COUNTIFS('CCS追っかけ'!$B$5:$B$504,$A21,'CCS追っかけ'!$J$5:$J$504,"CCS済")+COUNTIFS('CCS追っかけ'!$B$5:$B$504,$A21,'CCS追っかけ'!$P$5:$P$504,"✅正式",'CCS追っかけ'!$J$5:$J$504,"<>CCS済"))
B22: =IF($A22="","",IFERROR(IF(INDIRECT("'"&$A22&"'!B4")="","",INDIRECT("'"&$A22&"'!B4")),"")) | C22: =IF($A22="","",IFERROR(IF(INDIRECT("'"&$A22&"'!B6")="","",INDIRECT("'"&$A22&"'!B6")),"")) | D22: =IF($A22="","",IFERROR(IF(INDIRECT("'"&$A22&"'!B8")="","",INDIRECT("'"&$A22&"'!B8")),"")) | E22: =IF($A22="","",IFERROR(IF(INDIRECT("'"&$A22&"'!B24")="","",INDIRECT("'"&$A22&"'!B24")),"")) | F22: =IF($A22="","",IFERROR(IF(INDIRECT("'"&$A22&"'!B25")="","",INDIRECT("'"&$A22&"'!B25")),"")) | G22: =IF(OR($A22="",F22=""),"",IF(E22="フェーズ1",F22+'設定'!$B$4,IF(E22="フェーズ2",F22+'設定'!$B$5,""))) | H22: =IF(G22="","",G22-TODAY()) | I22: =IF($A22="","",IFERROR(IF(INDIRECT("'"&$A22&"'!B26")="","",INDIRECT("'"&$A22&"'!B26")),"")) | J22: =IF($A22="","",COUNTIFS('CCS追っかけ'!$B$5:$B$504,$A22,'CCS追っかけ'!$P$5:$P$504,"✅正式")) | K22: =IF($A22="","",COUNTIFS('CCS追っかけ'!$B$5:$B$504,$A22,'CCS追っかけ'!$D$5:$D$504,"<>",'CCS追っかけ'!$V$5:$V$504,"<>辞退")-J22) | L22: =IF(OR($A22="",I22="",I22=0),"",J22/I22) | M22: =IF(OR($A22="",I22="",F22=""),"",IF(J22>=I22,"🟢達成",IF(G22="","🟡進行中",IF(H22<0,"🔴期限超過",IF(AND(H22<='設定'!$B$7,J22<I22*0.8),"🔴期限間近",IF(J22>=I22*MIN(1,(TODAY()-F22)/(G22-F22)),"🟢順調",IF(J22>=I22*MIN(1,(TODAY()-F22)/(G22-F22))*'設定'!$B$6,"🟡要注意","🔴遅れ"))))))) | N22: =IF($A22="","",SUMIFS('日次ログ'!$D$5:$D$1504,'日次ログ'!$B$5:$B$1504,$A22,'日次ログ'!$A$5:$A$1504,">="&(TODAY()-6))) | O22: =IF($A22="","",SUMIFS('日次ログ'!$F$5:$F$1504,'日次ログ'!$B$5:$B$1504,$A22,'日次ログ'!$A$5:$A$1504,">="&(TODAY()-6))) | P22: =IF($A22="","",IF(COUNTIF('日次ログ'!$B$5:$B$1504,$A22)=0,"",_xlfn.MAXIFS('日次ログ'!$A$5:$A$1504,'日次ログ'!$B$5:$B$1504,$A22))) | Q22: =IF($A22="","",IFERROR(COUNTIF(INDIRECT("'"&$A22&"'!E9:E21"),"承諾")&" / "&COUNTA(INDIRECT("'"&$A22&"'!B9:B21")),"")) | R22: =IF($A22="","",IFERROR(IF(INDIRECT("'"&$A22&"'!B27")="","",INDIRECT("'"&$A22&"'!B27")),"")) | S22: =IF($A22="","",IFERROR(IF(INDIRECT("'"&$A22&"'!B28")="","",INDIRECT("'"&$A22&"'!B28")),"")) | T22: =IF($A22="","",COUNTIFS('入会後行動リスト'!$B$5:$B$2004,$A22,'入会後行動リスト'!$J$5:$J$2004,"期限超過")) | U22: =IF($A22="","",COUNTIFS('CCS追っかけ'!$B$5:$B$504,$A22,'CCS追っかけ'!$J$5:$J$504,"CCS済")+COUNTIFS('CCS追っかけ'!$B$5:$B$504,$A22,'CCS追っかけ'!$P$5:$P$504,"✅正式",'CCS追っかけ'!$J$5:$J$504,"<>CCS済"))
B23: =IF($A23="","",IFERROR(IF(INDIRECT("'"&$A23&"'!B4")="","",INDIRECT("'"&$A23&"'!B4")),"")) | C23: =IF($A23="","",IFERROR(IF(INDIRECT("'"&$A23&"'!B6")="","",INDIRECT("'"&$A23&"'!B6")),"")) | D23: =IF($A23="","",IFERROR(IF(INDIRECT("'"&$A23&"'!B8")="","",INDIRECT("'"&$A23&"'!B8")),"")) | E23: =IF($A23="","",IFERROR(IF(INDIRECT("'"&$A23&"'!B24")="","",INDIRECT("'"&$A23&"'!B24")),"")) | F23: =IF($A23="","",IFERROR(IF(INDIRECT("'"&$A23&"'!B25")="","",INDIRECT("'"&$A23&"'!B25")),"")) | G23: =IF(OR($A23="",F23=""),"",IF(E23="フェーズ1",F23+'設定'!$B$4,IF(E23="フェーズ2",F23+'設定'!$B$5,""))) | H23: =IF(G23="","",G23-TODAY()) | I23: =IF($A23="","",IFERROR(IF(INDIRECT("'"&$A23&"'!B26")="","",INDIRECT("'"&$A23&"'!B26")),"")) | J23: =IF($A23="","",COUNTIFS('CCS追っかけ'!$B$5:$B$504,$A23,'CCS追っかけ'!$P$5:$P$504,"✅正式")) | K23: =IF($A23="","",COUNTIFS('CCS追っかけ'!$B$5:$B$504,$A23,'CCS追っかけ'!$D$5:$D$504,"<>",'CCS追っかけ'!$V$5:$V$504,"<>辞退")-J23) | L23: =IF(OR($A23="",I23="",I23=0),"",J23/I23) | M23: =IF(OR($A23="",I23="",F23=""),"",IF(J23>=I23,"🟢達成",IF(G23="","🟡進行中",IF(H23<0,"🔴期限超過",IF(AND(H23<='設定'!$B$7,J23<I23*0.8),"🔴期限間近",IF(J23>=I23*MIN(1,(TODAY()-F23)/(G23-F23)),"🟢順調",IF(J23>=I23*MIN(1,(TODAY()-F23)/(G23-F23))*'設定'!$B$6,"🟡要注意","🔴遅れ"))))))) | N23: =IF($A23="","",SUMIFS('日次ログ'!$D$5:$D$1504,'日次ログ'!$B$5:$B$1504,$A23,'日次ログ'!$A$5:$A$1504,">="&(TODAY()-6))) | O23: =IF($A23="","",SUMIFS('日次ログ'!$F$5:$F$1504,'日次ログ'!$B$5:$B$1504,$A23,'日次ログ'!$A$5:$A$1504,">="&(TODAY()-6))) | P23: =IF($A23="","",IF(COUNTIF('日次ログ'!$B$5:$B$1504,$A23)=0,"",_xlfn.MAXIFS('日次ログ'!$A$5:$A$1504,'日次ログ'!$B$5:$B$1504,$A23))) | Q23: =IF($A23="","",IFERROR(COUNTIF(INDIRECT("'"&$A23&"'!E9:E21"),"承諾")&" / "&COUNTA(INDIRECT("'"&$A23&"'!B9:B21")),"")) | R23: =IF($A23="","",IFERROR(IF(INDIRECT("'"&$A23&"'!B27")="","",INDIRECT("'"&$A23&"'!B27")),"")) | S23: =IF($A23="","",IFERROR(IF(INDIRECT("'"&$A23&"'!B28")="","",INDIRECT("'"&$A23&"'!B28")),"")) | T23: =IF($A23="","",COUNTIFS('入会後行動リスト'!$B$5:$B$2004,$A23,'入会後行動リスト'!$J$5:$J$2004,"期限超過")) | U23: =IF($A23="","",COUNTIFS('CCS追っかけ'!$B$5:$B$504,$A23,'CCS追っかけ'!$J$5:$J$504,"CCS済")+COUNTIFS('CCS追っかけ'!$B$5:$B$504,$A23,'CCS追っかけ'!$P$5:$P$504,"✅正式",'CCS追っかけ'!$J$5:$J$504,"<>CCS済"))
B24: =IF($A24="","",IFERROR(IF(INDIRECT("'"&$A24&"'!B4")="","",INDIRECT("'"&$A24&"'!B4")),"")) | C24: =IF($A24="","",IFERROR(IF(INDIRECT("'"&$A24&"'!B6")="","",INDIRECT("'"&$A24&"'!B6")),"")) | D24: =IF($A24="","",IFERROR(IF(INDIRECT("'"&$A24&"'!B8")="","",INDIRECT("'"&$A24&"'!B8")),"")) | E24: =IF($A24="","",IFERROR(IF(INDIRECT("'"&$A24&"'!B24")="","",INDIRECT("'"&$A24&"'!B24")),"")) | F24: =IF($A24="","",IFERROR(IF(INDIRECT("'"&$A24&"'!B25")="","",INDIRECT("'"&$A24&"'!B25")),"")) | G24: =IF(OR($A24="",F24=""),"",IF(E24="フェーズ1",F24+'設定'!$B$4,IF(E24="フェーズ2",F24+'設定'!$B$5,""))) | H24: =IF(G24="","",G24-TODAY()) | I24: =IF($A24="","",IFERROR(IF(INDIRECT("'"&$A24&"'!B26")="","",INDIRECT("'"&$A24&"'!B26")),"")) | J24: =IF($A24="","",COUNTIFS('CCS追っかけ'!$B$5:$B$504,$A24,'CCS追っかけ'!$P$5:$P$504,"✅正式")) | K24: =IF($A24="","",COUNTIFS('CCS追っかけ'!$B$5:$B$504,$A24,'CCS追っかけ'!$D$5:$D$504,"<>",'CCS追っかけ'!$V$5:$V$504,"<>辞退")-J24) | L24: =IF(OR($A24="",I24="",I24=0),"",J24/I24) | M24: =IF(OR($A24="",I24="",F24=""),"",IF(J24>=I24,"🟢達成",IF(G24="","🟡進行中",IF(H24<0,"🔴期限超過",IF(AND(H24<='設定'!$B$7,J24<I24*0.8),"🔴期限間近",IF(J24>=I24*MIN(1,(TODAY()-F24)/(G24-F24)),"🟢順調",IF(J24>=I24*MIN(1,(TODAY()-F24)/(G24-F24))*'設定'!$B$6,"🟡要注意","🔴遅れ"))))))) | N24: =IF($A24="","",SUMIFS('日次ログ'!$D$5:$D$1504,'日次ログ'!$B$5:$B$1504,$A24,'日次ログ'!$A$5:$A$1504,">="&(TODAY()-6))) | O24: =IF($A24="","",SUMIFS('日次ログ'!$F$5:$F$1504,'日次ログ'!$B$5:$B$1504,$A24,'日次ログ'!$A$5:$A$1504,">="&(TODAY()-6))) | P24: =IF($A24="","",IF(COUNTIF('日次ログ'!$B$5:$B$1504,$A24)=0,"",_xlfn.MAXIFS('日次ログ'!$A$5:$A$1504,'日次ログ'!$B$5:$B$1504,$A24))) | Q24: =IF($A24="","",IFERROR(COUNTIF(INDIRECT("'"&$A24&"'!E9:E21"),"承諾")&" / "&COUNTA(INDIRECT("'"&$A24&"'!B9:B21")),"")) | R24: =IF($A24="","",IFERROR(IF(INDIRECT("'"&$A24&"'!B27")="","",INDIRECT("'"&$A24&"'!B27")),"")) | S24: =IF($A24="","",IFERROR(IF(INDIRECT("'"&$A24&"'!B28")="","",INDIRECT("'"&$A24&"'!B28")),"")) | T24: =IF($A24="","",COUNTIFS('入会後行動リスト'!$B$5:$B$2004,$A24,'入会後行動リスト'!$J$5:$J$2004,"期限超過")) | U24: =IF($A24="","",COUNTIFS('CCS追っかけ'!$B$5:$B$504,$A24,'CCS追っかけ'!$J$5:$J$504,"CCS済")+COUNTIFS('CCS追っかけ'!$B$5:$B$504,$A24,'CCS追っかけ'!$P$5:$P$504,"✅正式",'CCS追っかけ'!$J$5:$J$504,"<>CCS済"))
B25: =IF($A25="","",IFERROR(IF(INDIRECT("'"&$A25&"'!B4")="","",INDIRECT("'"&$A25&"'!B4")),"")) | C25: =IF($A25="","",IFERROR(IF(INDIRECT("'"&$A25&"'!B6")="","",INDIRECT("'"&$A25&"'!B6")),"")) | D25: =IF($A25="","",IFERROR(IF(INDIRECT("'"&$A25&"'!B8")="","",INDIRECT("'"&$A25&"'!B8")),"")) | E25: =IF($A25="","",IFERROR(IF(INDIRECT("'"&$A25&"'!B24")="","",INDIRECT("'"&$A25&"'!B24")),"")) | F25: =IF($A25="","",IFERROR(IF(INDIRECT("'"&$A25&"'!B25")="","",INDIRECT("'"&$A25&"'!B25")),"")) | G25: =IF(OR($A25="",F25=""),"",IF(E25="フェーズ1",F25+'設定'!$B$4,IF(E25="フェーズ2",F25+'設定'!$B$5,""))) | H25: =IF(G25="","",G25-TODAY()) | I25: =IF($A25="","",IFERROR(IF(INDIRECT("'"&$A25&"'!B26")="","",INDIRECT("'"&$A25&"'!B26")),"")) | J25: =IF($A25="","",COUNTIFS('CCS追っかけ'!$B$5:$B$504,$A25,'CCS追っかけ'!$P$5:$P$504,"✅正式")) | K25: =IF($A25="","",COUNTIFS('CCS追っかけ'!$B$5:$B$504,$A25,'CCS追っかけ'!$D$5:$D$504,"<>",'CCS追っかけ'!$V$5:$V$504,"<>辞退")-J25) | L25: =IF(OR($A25="",I25="",I25=0),"",J25/I25) | M25: =IF(OR($A25="",I25="",F25=""),"",IF(J25>=I25,"🟢達成",IF(G25="","🟡進行中",IF(H25<0,"🔴期限超過",IF(AND(H25<='設定'!$B$7,J25<I25*0.8),"🔴期限間近",IF(J25>=I25*MIN(1,(TODAY()-F25)/(G25-F25)),"🟢順調",IF(J25>=I25*MIN(1,(TODAY()-F25)/(G25-F25))*'設定'!$B$6,"🟡要注意","🔴遅れ"))))))) | N25: =IF($A25="","",SUMIFS('日次ログ'!$D$5:$D$1504,'日次ログ'!$B$5:$B$1504,$A25,'日次ログ'!$A$5:$A$1504,">="&(TODAY()-6))) | O25: =IF($A25="","",SUMIFS('日次ログ'!$F$5:$F$1504,'日次ログ'!$B$5:$B$1504,$A25,'日次ログ'!$A$5:$A$1504,">="&(TODAY()-6))) | P25: =IF($A25="","",IF(COUNTIF('日次ログ'!$B$5:$B$1504,$A25)=0,"",_xlfn.MAXIFS('日次ログ'!$A$5:$A$1504,'日次ログ'!$B$5:$B$1504,$A25))) | Q25: =IF($A25="","",IFERROR(COUNTIF(INDIRECT("'"&$A25&"'!E9:E21"),"承諾")&" / "&COUNTA(INDIRECT("'"&$A25&"'!B9:B21")),"")) | R25: =IF($A25="","",IFERROR(IF(INDIRECT("'"&$A25&"'!B27")="","",INDIRECT("'"&$A25&"'!B27")),"")) | S25: =IF($A25="","",IFERROR(IF(INDIRECT("'"&$A25&"'!B28")="","",INDIRECT("'"&$A25&"'!B28")),"")) | T25: =IF($A25="","",COUNTIFS('入会後行動リスト'!$B$5:$B$2004,$A25,'入会後行動リスト'!$J$5:$J$2004,"期限超過")) | U25: =IF($A25="","",COUNTIFS('CCS追っかけ'!$B$5:$B$504,$A25,'CCS追っかけ'!$J$5:$J$504,"CCS済")+COUNTIFS('CCS追っかけ'!$B$5:$B$504,$A25,'CCS追っかけ'!$P$5:$P$504,"✅正式",'CCS追っかけ'!$J$5:$J$504,"<>CCS済"))
B26: =IF($A26="","",IFERROR(IF(INDIRECT("'"&$A26&"'!B4")="","",INDIRECT("'"&$A26&"'!B4")),"")) | C26: =IF($A26="","",IFERROR(IF(INDIRECT("'"&$A26&"'!B6")="","",INDIRECT("'"&$A26&"'!B6")),"")) | D26: =IF($A26="","",IFERROR(IF(INDIRECT("'"&$A26&"'!B8")="","",INDIRECT("'"&$A26&"'!B8")),"")) | E26: =IF($A26="","",IFERROR(IF(INDIRECT("'"&$A26&"'!B24")="","",INDIRECT("'"&$A26&"'!B24")),"")) | F26: =IF($A26="","",IFERROR(IF(INDIRECT("'"&$A26&"'!B25")="","",INDIRECT("'"&$A26&"'!B25")),"")) | G26: =IF(OR($A26="",F26=""),"",IF(E26="フェーズ1",F26+'設定'!$B$4,IF(E26="フェーズ2",F26+'設定'!$B$5,""))) | H26: =IF(G26="","",G26-TODAY()) | I26: =IF($A26="","",IFERROR(IF(INDIRECT("'"&$A26&"'!B26")="","",INDIRECT("'"&$A26&"'!B26")),"")) | J26: =IF($A26="","",COUNTIFS('CCS追っかけ'!$B$5:$B$504,$A26,'CCS追っかけ'!$P$5:$P$504,"✅正式")) | K26: =IF($A26="","",COUNTIFS('CCS追っかけ'!$B$5:$B$504,$A26,'CCS追っかけ'!$D$5:$D$504,"<>",'CCS追っかけ'!$V$5:$V$504,"<>辞退")-J26) | L26: =IF(OR($A26="",I26="",I26=0),"",J26/I26) | M26: =IF(OR($A26="",I26="",F26=""),"",IF(J26>=I26,"🟢達成",IF(G26="","🟡進行中",IF(H26<0,"🔴期限超過",IF(AND(H26<='設定'!$B$7,J26<I26*0.8),"🔴期限間近",IF(J26>=I26*MIN(1,(TODAY()-F26)/(G26-F26)),"🟢順調",IF(J26>=I26*MIN(1,(TODAY()-F26)/(G26-F26))*'設定'!$B$6,"🟡要注意","🔴遅れ"))))))) | N26: =IF($A26="","",SUMIFS('日次ログ'!$D$5:$D$1504,'日次ログ'!$B$5:$B$1504,$A26,'日次ログ'!$A$5:$A$1504,">="&(TODAY()-6))) | O26: =IF($A26="","",SUMIFS('日次ログ'!$F$5:$F$1504,'日次ログ'!$B$5:$B$1504,$A26,'日次ログ'!$A$5:$A$1504,">="&(TODAY()-6))) | P26: =IF($A26="","",IF(COUNTIF('日次ログ'!$B$5:$B$1504,$A26)=0,"",_xlfn.MAXIFS('日次ログ'!$A$5:$A$1504,'日次ログ'!$B$5:$B$1504,$A26))) | Q26: =IF($A26="","",IFERROR(COUNTIF(INDIRECT("'"&$A26&"'!E9:E21"),"承諾")&" / "&COUNTA(INDIRECT("'"&$A26&"'!B9:B21")),"")) | R26: =IF($A26="","",IFERROR(IF(INDIRECT("'"&$A26&"'!B27")="","",INDIRECT("'"&$A26&"'!B27")),"")) | S26: =IF($A26="","",IFERROR(IF(INDIRECT("'"&$A26&"'!B28")="","",INDIRECT("'"&$A26&"'!B28")),"")) | T26: =IF($A26="","",COUNTIFS('入会後行動リスト'!$B$5:$B$2004,$A26,'入会後行動リスト'!$J$5:$J$2004,"期限超過")) | U26: =IF($A26="","",COUNTIFS('CCS追っかけ'!$B$5:$B$504,$A26,'CCS追っかけ'!$J$5:$J$504,"CCS済")+COUNTIFS('CCS追っかけ'!$B$5:$B$504,$A26,'CCS追っかけ'!$P$5:$P$504,"✅正式",'CCS追っかけ'!$J$5:$J$504,"<>CCS済"))
B27: =IF($A27="","",IFERROR(IF(INDIRECT("'"&$A27&"'!B4")="","",INDIRECT("'"&$A27&"'!B4")),"")) | C27: =IF($A27="","",IFERROR(IF(INDIRECT("'"&$A27&"'!B6")="","",INDIRECT("'"&$A27&"'!B6")),"")) | D27: =IF($A27="","",IFERROR(IF(INDIRECT("'"&$A27&"'!B8")="","",INDIRECT("'"&$A27&"'!B8")),"")) | E27: =IF($A27="","",IFERROR(IF(INDIRECT("'"&$A27&"'!B24")="","",INDIRECT("'"&$A27&"'!B24")),"")) | F27: =IF($A27="","",IFERROR(IF(INDIRECT("'"&$A27&"'!B25")="","",INDIRECT("'"&$A27&"'!B25")),"")) | G27: =IF(OR($A27="",F27=""),"",IF(E27="フェーズ1",F27+'設定'!$B$4,IF(E27="フェーズ2",F27+'設定'!$B$5,""))) | H27: =IF(G27="","",G27-TODAY()) | I27: =IF($A27="","",IFERROR(IF(INDIRECT("'"&$A27&"'!B26")="","",INDIRECT("'"&$A27&"'!B26")),"")) | J27: =IF($A27="","",COUNTIFS('CCS追っかけ'!$B$5:$B$504,$A27,'CCS追っかけ'!$P$5:$P$504,"✅正式")) | K27: =IF($A27="","",COUNTIFS('CCS追っかけ'!$B$5:$B$504,$A27,'CCS追っかけ'!$D$5:$D$504,"<>",'CCS追っかけ'!$V$5:$V$504,"<>辞退")-J27) | L27: =IF(OR($A27="",I27="",I27=0),"",J27/I27) | M27: =IF(OR($A27="",I27="",F27=""),"",IF(J27>=I27,"🟢達成",IF(G27="","🟡進行中",IF(H27<0,"🔴期限超過",IF(AND(H27<='設定'!$B$7,J27<I27*0.8),"🔴期限間近",IF(J27>=I27*MIN(1,(TODAY()-F27)/(G27-F27)),"🟢順調",IF(J27>=I27*MIN(1,(TODAY()-F27)/(G27-F27))*'設定'!$B$6,"🟡要注意","🔴遅れ"))))))) | N27: =IF($A27="","",SUMIFS('日次ログ'!$D$5:$D$1504,'日次ログ'!$B$5:$B$1504,$A27,'日次ログ'!$A$5:$A$1504,">="&(TODAY()-6))) | O27: =IF($A27="","",SUMIFS('日次ログ'!$F$5:$F$1504,'日次ログ'!$B$5:$B$1504,$A27,'日次ログ'!$A$5:$A$1504,">="&(TODAY()-6))) | P27: =IF($A27="","",IF(COUNTIF('日次ログ'!$B$5:$B$1504,$A27)=0,"",_xlfn.MAXIFS('日次ログ'!$A$5:$A$1504,'日次ログ'!$B$5:$B$1504,$A27))) | Q27: =IF($A27="","",IFERROR(COUNTIF(INDIRECT("'"&$A27&"'!E9:E21"),"承諾")&" / "&COUNTA(INDIRECT("'"&$A27&"'!B9:B21")),"")) | R27: =IF($A27="","",IFERROR(IF(INDIRECT("'"&$A27&"'!B27")="","",INDIRECT("'"&$A27&"'!B27")),"")) | S27: =IF($A27="","",IFERROR(IF(INDIRECT("'"&$A27&"'!B28")="","",INDIRECT("'"&$A27&"'!B28")),"")) | T27: =IF($A27="","",COUNTIFS('入会後行動リスト'!$B$5:$B$2004,$A27,'入会後行動リスト'!$J$5:$J$2004,"期限超過")) | U27: =IF($A27="","",COUNTIFS('CCS追っかけ'!$B$5:$B$504,$A27,'CCS追っかけ'!$J$5:$J$504,"CCS済")+COUNTIFS('CCS追っかけ'!$B$5:$B$504,$A27,'CCS追っかけ'!$P$5:$P$504,"✅正式",'CCS追っかけ'!$J$5:$J$504,"<>CCS済"))

Sheet 全体管理
A1: 全体管理（各LDシートから自動集約・入力不要）
A2: 名前の後ろの（打診中）等は声かけ状況。承諾済みは名前のみ表示
A4: ローンチディレクター | B4: 管轄エリア | C4: チャプター名 | D4: 定例会日時 | E4: 初回定例会 | F4: CCS担当① | G4: CCS担当② | H4: CCS担当③ | I4: CCS担当④ | J4: MS・メンター① | K4: MS・メンター② | L4: MS・メンター③ | M4: MS・メンター④ | N4: 全体サポート | O4: その他・必要な役割 | P4: 進捗・メモ
A5: ='📊ダッシュボード'!A8&"" | B5: =IF($A5="","",IFERROR(IF(INDIRECT("'"&$A5&"'!B4")="","",INDIRECT("'"&$A5&"'!B4")),"")) | C5: =IF($A5="","",IFERROR(IF(INDIRECT("'"&$A5&"'!B6")="","",INDIRECT("'"&$A5&"'!B6")),"")) | D5: =IF($A5="","",IFERROR(IF(INDIRECT("'"&$A5&"'!B7")="","",INDIRECT("'"&$A5&"'!B7")),"")) | E5: =IF($A5="","",IFERROR(IF(INDIRECT("'"&$A5&"'!B8")="","",INDIRECT("'"&$A5&"'!B8")),"")) | F5: =IF($A5="","",IFERROR(IF(INDIRECT("'"&$A5&"'!B9")="","",INDIRECT("'"&$A5&"'!B9")&IF(INDIRECT("'"&$A5&"'!E9")="承諾",""," （"&INDIRECT("'"&$A5&"'!E9")&"）")),"")) | G5: =IF($A5="","",IFERROR(IF(INDIRECT("'"&$A5&"'!B10")="","",INDIRECT("'"&$A5&"'!B10")&IF(INDIRECT("'"&$A5&"'!E10")="承諾",""," （"&INDIRECT("'"&$A5&"'!E10")&"）")),"")) | H5: =IF($A5="","",IFERROR(IF(INDIRECT("'"&$A5&"'!B11")="","",INDIRECT("'"&$A5&"'!B11")&IF(INDIRECT("'"&$A5&"'!E11")="承諾",""," （"&INDIRECT("'"&$A5&"'!E11")&"）")),"")) | I5: =IF($A5="","",IFERROR(IF(INDIRECT("'"&$A5&"'!B12")="","",INDIRECT("'"&$A5&"'!B12")&IF(INDIRECT("'"&$A5&"'!E12")="承諾",""," （"&INDIRECT("'"&$A5&"'!E12")&"）")),"")) | J5: =IF($A5="","",IFERROR(IF(INDIRECT("'"&$A5&"'!B13")="","",INDIRECT("'"&$A5&"'!B13")&IF(INDIRECT("'"&$A5&"'!E13")="承諾",""," （"&INDIRECT("'"&$A5&"'!E13")&"）")),"")) | K5: =IF($A5="","",IFERROR(IF(INDIRECT("'"&$A5&"'!B14")="","",INDIRECT("'"&$A5&"'!B14")&IF(INDIRECT("'"&$A5&"'!E14")="承諾",""," （"&INDIRECT("'"&$A5&"'!E14")&"）")),"")) | L5: =IF($A5="","",IFERROR(IF(INDIRECT("'"&$A5&"'!B15")="","",INDIRECT("'"&$A5&"'!B15")&IF(INDIRECT("'"&$A5&"'!E15")="承諾",""," （"&INDIRECT("'"&$A5&"'!E15")&"）")),"")) | M5: =IF($A5="","",IFERROR(IF(INDIRECT("'"&$A5&"'!B16")="","",INDIRECT("'"&$A5&"'!B16")&IF(INDIRECT("'"&$A5&"'!E16")="承諾",""," （"&INDIRECT("'"&$A5&"'!E16")&"）")),"")) | N5: =IF($A5="","",IFERROR(_xlfn.TEXTJOIN("、",TRUE,INDIRECT("'"&$A5&"'!B17:B20")),"")) | O5: =IF($A5="","",IFERROR(IF(INDIRECT("'"&$A5&"'!B21")="","",INDIRECT("'"&$A5&"'!B21")&IF(INDIRECT("'"&$A5&"'!E21")="承諾",""," （"&INDIRECT("'"&$A5&"'!E21")&"）")),"")) | P5: =IF($A5="","",IFERROR(IF(INDIRECT("'"&$A5&"'!B27")="","",INDIRECT("'"&$A5&"'!B27")),""))
A6: ='📊ダッシュボード'!A9&"" | B6: =IF($A6="","",IFERROR(IF(INDIRECT("'"&$A6&"'!B4")="","",INDIRECT("'"&$A6&"'!B4")),"")) | C6: =IF($A6="","",IFERROR(IF(INDIRECT("'"&$A6&"'!B6")="","",INDIRECT("'"&$A6&"'!B6")),"")) | D6: =IF($A6="","",IFERROR(IF(INDIRECT("'"&$A6&"'!B7")="","",INDIRECT("'"&$A6&"'!B7")),"")) | E6: =IF($A6="","",IFERROR(IF(INDIRECT("'"&$A6&"'!B8")="","",INDIRECT("'"&$A6&"'!B8")),"")) | F6: =IF($A6="","",IFERROR(IF(INDIRECT("'"&$A6&"'!B9")="","",INDIRECT("'"&$A6&"'!B9")&IF(INDIRECT("'"&$A6&"'!E9")="承諾",""," （"&INDIRECT("'"&$A6&"'!E9")&"）")),"")) | G6: =IF($A6="","",IFERROR(IF(INDIRECT("'"&$A6&"'!B10")="","",INDIRECT("'"&$A6&"'!B10")&IF(INDIRECT("'"&$A6&"'!E10")="承諾",""," （"&INDIRECT("'"&$A6&"'!E10")&"）")),"")) | H6: =IF($A6="","",IFERROR(IF(INDIRECT("'"&$A6&"'!B11")="","",INDIRECT("'"&$A6&"'!B11")&IF(INDIRECT("'"&$A6&"'!E11")="承諾",""," （"&INDIRECT("'"&$A6&"'!E11")&"）")),"")) | I6: =IF($A6="","",IFERROR(IF(INDIRECT("'"&$A6&"'!B12")="","",INDIRECT("'"&$A6&"'!B12")&IF(INDIRECT("'"&$A6&"'!E12")="承諾",""," （"&INDIRECT("'"&$A6&"'!E12")&"）")),"")) | J6: =IF($A6="","",IFERROR(IF(INDIRECT("'"&$A6&"'!B13")="","",INDIRECT("'"&$A6&"'!B13")&IF(INDIRECT("'"&$A6&"'!E13")="承諾",""," （"&INDIRECT("'"&$A6&"'!E13")&"）")),"")) | K6: =IF($A6="","",IFERROR(IF(INDIRECT("'"&$A6&"'!B14")="","",INDIRECT("'"&$A6&"'!B14")&IF(INDIRECT("'"&$A6&"'!E14")="承諾",""," （"&INDIRECT("'"&$A6&"'!E14")&"）")),"")) | L6: =IF($A6="","",IFERROR(IF(INDIRECT("'"&$A6&"'!B15")="","",INDIRECT("'"&$A6&"'!B15")&IF(INDIRECT("'"&$A6&"'!E15")="承諾",""," （"&INDIRECT("'"&$A6&"'!E15")&"）")),"")) | M6: =IF($A6="","",IFERROR(IF(INDIRECT("'"&$A6&"'!B16")="","",INDIRECT("'"&$A6&"'!B16")&IF(INDIRECT("'"&$A6&"'!E16")="承諾",""," （"&INDIRECT("'"&$A6&"'!E16")&"）")),"")) | N6: =IF($A6="","",IFERROR(_xlfn.TEXTJOIN("、",TRUE,INDIRECT("'"&$A6&"'!B17:B20")),"")) | O6: =IF($A6="","",IFERROR(IF(INDIRECT("'"&$A6&"'!B21")="","",INDIRECT("'"&$A6&"'!B21")&IF(INDIRECT("'"&$A6&"'!E21")="承諾",""," （"&INDIRECT("'"&$A6&"'!E21")&"）")),"")) | P6: =IF($A6="","",IFERROR(IF(INDIRECT("'"&$A6&"'!B27")="","",INDIRECT("'"&$A6&"'!B27")),""))
A7: ='📊ダッシュボード'!A10&"" | B7: =IF($A7="","",IFERROR(IF(INDIRECT("'"&$A7&"'!B4")="","",INDIRECT("'"&$A7&"'!B4")),"")) | C7: =IF($A7="","",IFERROR(IF(INDIRECT("'"&$A7&"'!B6")="","",INDIRECT("'"&$A7&"'!B6")),"")) | D7: =IF($A7="","",IFERROR(IF(INDIRECT("'"&$A7&"'!B7")="","",INDIRECT("'"&$A7&"'!B7")),"")) | E7: =IF($A7="","",IFERROR(IF(INDIRECT("'"&$A7&"'!B8")="","",INDIRECT("'"&$A7&"'!B8")),"")) | F7: =IF($A7="","",IFERROR(IF(INDIRECT("'"&$A7&"'!B9")="","",INDIRECT("'"&$A7&"'!B9")&IF(INDIRECT("'"&$A7&"'!E9")="承諾",""," （"&INDIRECT("'"&$A7&"'!E9")&"）")),"")) | G7: =IF($A7="","",IFERROR(IF(INDIRECT("'"&$A7&"'!B10")="","",INDIRECT("'"&$A7&"'!B10")&IF(INDIRECT("'"&$A7&"'!E10")="承諾",""," （"&INDIRECT("'"&$A7&"'!E10")&"）")),"")) | H7: =IF($A7="","",IFERROR(IF(INDIRECT("'"&$A7&"'!B11")="","",INDIRECT("'"&$A7&"'!B11")&IF(INDIRECT("'"&$A7&"'!E11")="承諾",""," （"&INDIRECT("'"&$A7&"'!E11")&"）")),"")) | I7: =IF($A7="","",IFERROR(IF(INDIRECT("'"&$A7&"'!B12")="","",INDIRECT("'"&$A7&"'!B12")&IF(INDIRECT("'"&$A7&"'!E12")="承諾",""," （"&INDIRECT("'"&$A7&"'!E12")&"）")),"")) | J7: =IF($A7="","",IFERROR(IF(INDIRECT("'"&$A7&"'!B13")="","",INDIRECT("'"&$A7&"'!B13")&IF(INDIRECT("'"&$A7&"'!E13")="承諾",""," （"&INDIRECT("'"&$A7&"'!E13")&"）")),"")) | K7: =IF($A7="","",IFERROR(IF(INDIRECT("'"&$A7&"'!B14")="","",INDIRECT("'"&$A7&"'!B14")&IF(INDIRECT("'"&$A7&"'!E14")="承諾",""," （"&INDIRECT("'"&$A7&"'!E14")&"）")),"")) | L7: =IF($A7="","",IFERROR(IF(INDIRECT("'"&$A7&"'!B15")="","",INDIRECT("'"&$A7&"'!B15")&IF(INDIRECT("'"&$A7&"'!E15")="承諾",""," （"&INDIRECT("'"&$A7&"'!E15")&"）")),"")) | M7: =IF($A7="","",IFERROR(IF(INDIRECT("'"&$A7&"'!B16")="","",INDIRECT("'"&$A7&"'!B16")&IF(INDIRECT("'"&$A7&"'!E16")="承諾",""," （"&INDIRECT("'"&$A7&"'!E16")&"）")),"")) | N7: =IF($A7="","",IFERROR(_xlfn.TEXTJOIN("、",TRUE,INDIRECT("'"&$A7&"'!B17:B20")),"")) | O7: =IF($A7="","",IFERROR(IF(INDIRECT("'"&$A7&"'!B21")="","",INDIRECT("'"&$A7&"'!B21")&IF(INDIRECT("'"&$A7&"'!E21")="承諾",""," （"&INDIRECT("'"&$A7&"'!E21")&"）")),"")) | P7: =IF($A7="","",IFERROR(IF(INDIRECT("'"&$A7&"'!B27")="","",INDIRECT("'"&$A7&"'!B27")),""))
A8: ='📊ダッシュボード'!A11&"" | B8: =IF($A8="","",IFERROR(IF(INDIRECT("'"&$A8&"'!B4")="","",INDIRECT("'"&$A8&"'!B4")),"")) | C8: =IF($A8="","",IFERROR(IF(INDIRECT("'"&$A8&"'!B6")="","",INDIRECT("'"&$A8&"'!B6")),"")) | D8: =IF($A8="","",IFERROR(IF(INDIRECT("'"&$A8&"'!B7")="","",INDIRECT("'"&$A8&"'!B7")),"")) | E8: =IF($A8="","",IFERROR(IF(INDIRECT("'"&$A8&"'!B8")="","",INDIRECT("'"&$A8&"'!B8")),"")) | F8: =IF($A8="","",IFERROR(IF(INDIRECT("'"&$A8&"'!B9")="","",INDIRECT("'"&$A8&"'!B9")&IF(INDIRECT("'"&$A8&"'!E9")="承諾",""," （"&INDIRECT("'"&$A8&"'!E9")&"）")),"")) | G8: =IF($A8="","",IFERROR(IF(INDIRECT("'"&$A8&"'!B10")="","",INDIRECT("'"&$A8&"'!B10")&IF(INDIRECT("'"&$A8&"'!E10")="承諾",""," （"&INDIRECT("'"&$A8&"'!E10")&"）")),"")) | H8: =IF($A8="","",IFERROR(IF(INDIRECT("'"&$A8&"'!B11")="","",INDIRECT("'"&$A8&"'!B11")&IF(INDIRECT("'"&$A8&"'!E11")="承諾",""," （"&INDIRECT("'"&$A8&"'!E11")&"）")),"")) | I8: =IF($A8="","",IFERROR(IF(INDIRECT("'"&$A8&"'!B12")="","",INDIRECT("'"&$A8&"'!B12")&IF(INDIRECT("'"&$A8&"'!E12")="承諾",""," （"&INDIRECT("'"&$A8&"'!E12")&"）")),"")) | J8: =IF($A8="","",IFERROR(IF(INDIRECT("'"&$A8&"'!B13")="","",INDIRECT("'"&$A8&"'!B13")&IF(INDIRECT("'"&$A8&"'!E13")="承諾",""," （"&INDIRECT("'"&$A8&"'!E13")&"）")),"")) | K8: =IF($A8="","",IFERROR(IF(INDIRECT("'"&$A8&"'!B14")="","",INDIRECT("'"&$A8&"'!B14")&IF(INDIRECT("'"&$A8&"'!E14")="承諾",""," （"&INDIRECT("'"&$A8&"'!E14")&"）")),"")) | L8: =IF($A8="","",IFERROR(IF(INDIRECT("'"&$A8&"'!B15")="","",INDIRECT("'"&$A8&"'!B15")&IF(INDIRECT("'"&$A8&"'!E15")="承諾",""," （"&INDIRECT("'"&$A8&"'!E15")&"）")),"")) | M8: =IF($A8="","",IFERROR(IF(INDIRECT("'"&$A8&"'!B16")="","",INDIRECT("'"&$A8&"'!B16")&IF(INDIRECT("'"&$A8&"'!E16")="承諾",""," （"&INDIRECT("'"&$A8&"'!E16")&"）")),"")) | N8: =IF($A8="","",IFERROR(_xlfn.TEXTJOIN("、",TRUE,INDIRECT("'"&$A8&"'!B17:B20")),"")) | O8: =IF($A8="","",IFERROR(IF(INDIRECT("'"&$A8&"'!B21")="","",INDIRECT("'"&$A8&"'!B21")&IF(INDIRECT("'"&$A8&"'!E21")="承諾",""," （"&INDIRECT("'"&$A8&"'!E21")&"）")),"")) | P8: =IF($A8="","",IFERROR(IF(INDIRECT("'"&$A8&"'!B27")="","",INDIRECT("'"&$A8&"'!B27")),""))
A9: ='📊ダッシュボード'!A12&"" | B9: =IF($A9="","",IFERROR(IF(INDIRECT("'"&$A9&"'!B4")="","",INDIRECT("'"&$A9&"'!B4")),"")) | C9: =IF($A9="","",IFERROR(IF(INDIRECT("'"&$A9&"'!B6")="","",INDIRECT("'"&$A9&"'!B6")),"")) | D9: =IF($A9="","",IFERROR(IF(INDIRECT("'"&$A9&"'!B7")="","",INDIRECT("'"&$A9&"'!B7")),"")) | E9: =IF($A9="","",IFERROR(IF(INDIRECT("'"&$A9&"'!B8")="","",INDIRECT("'"&$A9&"'!B8")),"")) | F9: =IF($A9="","",IFERROR(IF(INDIRECT("'"&$A9&"'!B9")="","",INDIRECT("'"&$A9&"'!B9")&IF(INDIRECT("'"&$A9&"'!E9")="承諾",""," （"&INDIRECT("'"&$A9&"'!E9")&"）")),"")) | G9: =IF($A9="","",IFERROR(IF(INDIRECT("'"&$A9&"'!B10")="","",INDIRECT("'"&$A9&"'!B10")&IF(INDIRECT("'"&$A9&"'!E10")="承諾",""," （"&INDIRECT("'"&$A9&"'!E10")&"）")),"")) | H9: =IF($A9="","",IFERROR(IF(INDIRECT("'"&$A9&"'!B11")="","",INDIRECT("'"&$A9&"'!B11")&IF(INDIRECT("'"&$A9&"'!E11")="承諾",""," （"&INDIRECT("'"&$A9&"'!E11")&"）")),"")) | I9: =IF($A9="","",IFERROR(IF(INDIRECT("'"&$A9&"'!B12")="","",INDIRECT("'"&$A9&"'!B12")&IF(INDIRECT("'"&$A9&"'!E12")="承諾",""," （"&INDIRECT("'"&$A9&"'!E12")&"）")),"")) | J9: =IF($A9="","",IFERROR(IF(INDIRECT("'"&$A9&"'!B13")="","",INDIRECT("'"&$A9&"'!B13")&IF(INDIRECT("'"&$A9&"'!E13")="承諾",""," （"&INDIRECT("'"&$A9&"'!E13")&"）")),"")) | K9: =IF($A9="","",IFERROR(IF(INDIRECT("'"&$A9&"'!B14")="","",INDIRECT("'"&$A9&"'!B14")&IF(INDIRECT("'"&$A9&"'!E14")="承諾",""," （"&INDIRECT("'"&$A9&"'!E14")&"）")),"")) | L9: =IF($A9="","",IFERROR(IF(INDIRECT("'"&$A9&"'!B15")="","",INDIRECT("'"&$A9&"'!B15")&IF(INDIRECT("'"&$A9&"'!E15")="承諾",""," （"&INDIRECT("'"&$A9&"'!E15")&"）")),"")) | M9: =IF($A9="","",IFERROR(IF(INDIRECT("'"&$A9&"'!B16")="","",INDIRECT("'"&$A9&"'!B16")&IF(INDIRECT("'"&$A9&"'!E16")="承諾",""," （"&INDIRECT("'"&$A9&"'!E16")&"）")),"")) | N9: =IF($A9="","",IFERROR(_xlfn.TEXTJOIN("、",TRUE,INDIRECT("'"&$A9&"'!B17:B20")),"")) | O9: =IF($A9="","",IFERROR(IF(INDIRECT("'"&$A9&"'!B21")="","",INDIRECT("'"&$A9&"'!B21")&IF(INDIRECT("'"&$A9&"'!E21")="承諾",""," （"&INDIRECT("'"&$A9&"'!E21")&"）")),"")) | P9: =IF($A9="","",IFERROR(IF(INDIRECT("'"&$A9&"'!B27")="","",INDIRECT("'"&$A9&"'!B27")),""))
A10: ='📊ダッシュボード'!A13&"" | B10: =IF($A10="","",IFERROR(IF(INDIRECT("'"&$A10&"'!B4")="","",INDIRECT("'"&$A10&"'!B4")),"")) | C10: =IF($A10="","",IFERROR(IF(INDIRECT("'"&$A10&"'!B6")="","",INDIRECT("'"&$A10&"'!B6")),"")) | D10: =IF($A10="","",IFERROR(IF(INDIRECT("'"&$A10&"'!B7")="","",INDIRECT("'"&$A10&"'!B7")),"")) | E10: =IF($A10="","",IFERROR(IF(INDIRECT("'"&$A10&"'!B8")="","",INDIRECT("'"&$A10&"'!B8")),"")) | F10: =IF($A10="","",IFERROR(IF(INDIRECT("'"&$A10&"'!B9")="","",INDIRECT("'"&$A10&"'!B9")&IF(INDIRECT("'"&$A10&"'!E9")="承諾",""," （"&INDIRECT("'"&$A10&"'!E9")&"）")),"")) | G10: =IF($A10="","",IFERROR(IF(INDIRECT("'"&$A10&"'!B10")="","",INDIRECT("'"&$A10&"'!B10")&IF(INDIRECT("'"&$A10&"'!E10")="承諾",""," （"&INDIRECT("'"&$A10&"'!E10")&"）")),"")) | H10: =IF($A10="","",IFERROR(IF(INDIRECT("'"&$A10&"'!B11")="","",INDIRECT("'"&$A10&"'!B11")&IF(INDIRECT("'"&$A10&"'!E11")="承諾",""," （"&INDIRECT("'"&$A10&"'!E11")&"）")),"")) | I10: =IF($A10="","",IFERROR(IF(INDIRECT("'"&$A10&"'!B12")="","",INDIRECT("'"&$A10&"'!B12")&IF(INDIRECT("'"&$A10&"'!E12")="承諾",""," （"&INDIRECT("'"&$A10&"'!E12")&"）")),"")) | J10: =IF($A10="","",IFERROR(IF(INDIRECT("'"&$A10&"'!B13")="","",INDIRECT("'"&$A10&"'!B13")&IF(INDIRECT("'"&$A10&"'!E13")="承諾",""," （"&INDIRECT("'"&$A10&"'!E13")&"）")),"")) | K10: =IF($A10="","",IFERROR(IF(INDIRECT("'"&$A10&"'!B14")="","",INDIRECT("'"&$A10&"'!B14")&IF(INDIRECT("'"&$A10&"'!E14")="承諾",""," （"&INDIRECT("'"&$A10&"'!E14")&"）")),"")) | L10: =IF($A10="","",IFERROR(IF(INDIRECT("'"&$A10&"'!B15")="","",INDIRECT("'"&$A10&"'!B15")&IF(INDIRECT("'"&$A10&"'!E15")="承諾",""," （"&INDIRECT("'"&$A10&"'!E15")&"）")),"")) | M10: =IF($A10="","",IFERROR(IF(INDIRECT("'"&$A10&"'!B16")="","",INDIRECT("'"&$A10&"'!B16")&IF(INDIRECT("'"&$A10&"'!E16")="承諾",""," （"&INDIRECT("'"&$A10&"'!E16")&"）")),"")) | N10: =IF($A10="","",IFERROR(_xlfn.TEXTJOIN("、",TRUE,INDIRECT("'"&$A10&"'!B17:B20")),"")) | O10: =IF($A10="","",IFERROR(IF(INDIRECT("'"&$A10&"'!B21")="","",INDIRECT("'"&$A10&"'!B21")&IF(INDIRECT("'"&$A10&"'!E21")="承諾",""," （"&INDIRECT("'"&$A10&"'!E21")&"）")),"")) | P10: =IF($A10="","",IFERROR(IF(INDIRECT("'"&$A10&"'!B27")="","",INDIRECT("'"&$A10&"'!B27")),""))
